Workbook

Sheet About
A1: SoCEUtiNTY Share of Components Energy Use that is New This Year | B1: California | C1: 46251
A3: Sources: | B3: Share of commercial floorspace that is new
B4: EIA
B5: 2017
B6: Annual Energy Outlook 2017
B7: https://www.eia.gov/outlooks/aeo/excel/aeotab_5.xlsx
B8: 5. Commercial Sector Key Indicators and Consumption
B10: Number of homes
B11: EIA
B12: 2017
B13: Annual Energy Outlook 2017
B14: https://www.eia.gov/outlooks/aeo/excel/aeotab_4.xlsx
B15: 4. Residential Sector Key Indicators and Consumption
B17: Share of homes that are new
B18: EIA
B19: 2017
B20: Residential Demand Module of the National Energy Modeling System: Model Documentation
B21: https://www.eia.gov/outlooks/aeo/nems/documentation/residential/pdf/m067(2017).pdf
B22: Page 56, Existing housing evolution rate
B24: Replacement rate of components in surviving buildings
B25: See bldgs/CL variable
A27: About
A28: This variable is used to estimate the share of BAU component energy use
A29: that is new (i.e. from newly installed components) each year. This includes
A30: both components to serve new buildings (demand growth) and components
A31: to replace retiring components.
A33: The "envelope" value in this variable does not matter, because envelope
A34: does not itself use energy. To avoid confusion, envelope is assigned
A35: a value of zero.
A37: We separately estimate the share of buildings that are new (whose components
A38: are all new) and the share of components in surviving buildings that are
A39: replaced each year. We consider the share of surviving buildings and
A40: new buildings to properly calculate overall component replacement rates.
... A53: 2026-08-17: recalibrated on the 2026-08-03 BCEU vintage. SoCEUtiNTY[bt,bc] = SYCEU_sum / (CL x BCEU_sum(2025)), the value that removes the step in "Retiring Components Potential Energy Use Summed Across Fuels" at t* = 2025 + CL. Full precision (6 significant figures): rounding to 3 decimals would re-introduce a step of up to 0.93%. Jumps remaining in that variable after 2040 come from the BCEU trajectory itself, not from this coefficient. Derivation: state-data-forecast qc/soceutinty_smoothness_calibration.py

Sheet Calibration Helper
A3: When Calibrating, place the current values here (default is 1/component lifetime)
B4: Lifetime (yr) | C4: urban residential | D4: rural residential | E4: commercial
A5: heating | B5: 19 | C5: 0.052631579 | D5: 0.052631579 | E5: 0.052631579
A6: cooling and ventilation | B6: 15.833333 | C6: 0.0625 | D6: 0.0625 | E6: 0.0625
A7: envelope | B7: 51.818182 | C7: 0 | D7: 0 | E7: 0
A8: lighting | B8: 9.1324201 | C8: 0.11111111 | D8: 0.11111111 | E8: 0.11111111
A9: appliances | B9: 13.533333 | C9: 0.071428571 | D9: 0.071428571 | E9: 0.071428571
A10: other component | B10: 15.4 | C10: 0.066666667 | D10: 0.066666667 | E10: 0.066666667
A14: Paste from default run (Retiring Components Potential Energy Use Summed Across Fuels)
A15: Time (Time) | B15: 2019 | C15: 2020 | D15: 2021 | E15: 2022 | F15: 2023 | G15: 2024 | H15: 2025 | I15: 2026 | J15: 2027 | K15: 2028 | L15: 2029 | M15: 2030 | N15: 2031 | O15: 2032 | P15: 2033 | Q15: 2034 | R15: 2035 | S15: 2036 | T15: 2037 | U15: 2038 | V15: 2039 | W15: 2040 | X15: 2041 | Y15: 2042 | Z15: 2043 | AA15: 2044 | AB15: 2045 | AC15: 2046 | AD15: 2047 | AE15: 2048 | AF15: 2049 | AG15: 2050
A16: Retiring Components Potential Energy Use Summed Across Fuels[urban residential,heating] : MostRecentRun | B16: 6.65222 | C16: 6.65222 | D16: 6.65222 | E16: 6.65222 | F16: 6.65222 | G16: 6.65222 | H16: 6.65222 | I16: 6.65222 | J16: 6.65222 | K16: 6.65222 | L16: 6.65222 | M16: 6.65222 | N16: 6.65222 | O16: 6.65222 | P16: 6.65222 | Q16: 6.65222 | R16: 6.65222 | S16: 6.65222 | T16: 6.65222 | U16: 6.49037 | V16: 6.54683 | W16: 6.59368 | X16: 6.6324 | Y16: 6.66331 | Z16: 6.68649 | AA16: 6.70387 | AB16: 6.71764 | AC16: 6.73185 | AD16: 6.74231 | AE16: 6.75137 | AF16: 6.75787 | AG16: 6.769
A17: Retiring Components Potential Energy Use Summed Across Fuels[urban residential,cooling and ventilation] : MostRecentRun | B17: 175.75 | C17: 175.75 | D17: 175.75 | E17: 175.75 | F17: 175.75 | G17: 175.75 | H17: 175.75 | I17: 175.75 | J17: 175.75 | K17: 175.75 | L17: 175.75 | M17: 175.75 | N17: 175.75 | O17: 175.75 | P17: 175.75 | Q17: 175.75 | R17: 165.776 | S17: 157.764 | T17: 150.428 | U17: 143.562 | V17: 137.379 | W17: 131.868 | X17: 126.739 | Y17: 122.735 | Z17: 119.382 | AA17: 116.664 | AB17: 114.559 | AC17: 112.959 | AD17: 111.419 | AE17: 110.409 | AF17: 109.538 | AG17: 108.747
A18: Retiring Components Potential Energy Use Summed Across Fuels[urban residential,envelope] : MostRecentRun | B18: 0 | C18: 0 | D18: 0 | E18: 0 | F18: 0 | G18: 0 | H18: 0 | I18: 0 | J18: 0 | K18: 0 | L18: 0 | M18: 0 | N18: 0 | O18: 0 | P18: 0 | Q18: 0 | R18: 0 | S18: 0 | T18: 0 | U18: 0 | V18: 0 | W18: 0 | X18: 0 | Y18: 0 | Z18: 0 | AA18: 0 | AB18: 0 | AC18: 0 | AD18: 0 | AE18: 0 | AF18: 0 | AG18: 0
A19: Retiring Components Potential Energy Use Summed Across Fuels[urban residential,lighting] : MostRecentRun | B19: 428.264 | C19: 428.264 | D19: 428.264 | E19: 428.264 | F19: 428.264 | G19: 428.264 | H19: 428.264 | I19: 428.264 | J19: 428.264 | K19: 428.264 | L19: 375.801 | M19: 365.754 | N19: 358.497 | O19: 351.45 | P19: 344.796 | Q19: 340.271 | R19: 337.818 | S19: 335.922 | T19: 333.712 | U19: 331.528 | V19: 329.592 | W19: 328.419 | X19: 327.969 | Y19: 327.748 | Z19: 327.258 | AA19: 326.517 | AB19: 324.586 | AC19: 322.297 | AD19: 319.749 | AE19: 317.116 | AF19: 314.516 | AG19: 308.491
A20: Retiring Components Potential Energy Use Summed Across Fuels[urban residential,appliances] : MostRecentRun | B20: 3.28439 | C20: 3.28439 | D20: 3.28439 | E20: 3.28439 | F20: 3.28439 | G20: 3.28439 | H20: 3.28439 | I20: 3.28439 | J20: 3.28439 | K20: 3.28439 | L20: 3.28439 | M20: 3.28439 | N20: 3.28439 | O20: 3.28439 | P20: 2.75582 | Q20: 2.73336 | R20: 2.71285 | S20: 2.69303 | T20: 2.6758 | U20: 2.6614 | V20: 2.65069 | W20: 2.64515 | X20: 2.64312 | Y20: 2.64469 | Z20: 2.649 | AA20: 2.6572 | AB20: 2.6675 | AC20: 2.68026 | AD20: 2.69279 | AE20: 2.70706 | AF20: 2.72154 | AG20: 2.73759
A21: Retiring Components Potential Energy Use Summed Across Fuels[urban residential,other component] : MostRecentRun | B21: 1.45727 | C21: 1.45727 | D21: 1.45727 | E21: 1.45727 | F21: 1.45727 | G21: 1.45727 | H21: 1.45727 | I21: 1.45727 | J21: 1.45727 | K21: 1.45727 | L21: 1.45727 | M21: 1.45727 | N21: 1.45727 | O21: 1.45727 | P21: 1.45727 | Q21: 1.45727 | R21: 1.47158 | S21: 1.48272 | T21: 1.499 | U21: 1.51635 | V21: 1.53606 | W21: 1.55686 | X21: 1.57416 | Y21: 1.5941 | Z21: 1.61603 | AA21: 1.63718 | AB21: 1.65693 | AC21: 1.67707 | AD21: 1.69809 | AE21: 1.72092 | AF21: 1.74595 | AG21: 1.77115
A22: Retiring Components Potential Energy Use Summed Across Fuels[rural residential,heating] : MostRecentRun | B22: 2.82388 | C22: 2.82388 | D22: 2.82388 | E22: 2.82388 | F22: 2.82388 | G22: 2.82388 | H22: 2.82388 | I22: 2.82388 | J22: 2.82388 | K22: 2.82388 | L22: 2.82388 | M22: 2.82388 | N22: 2.82388 | O22: 2.82388 | P22: 2.82388 | Q22: 2.82388 | R22: 2.82388 | S22: 2.82388 | T22: 2.82388 | U22: 2.75517 | V22: 2.77914 | W22: 2.79903 | X22: 2.81546 | Y22: 2.82858 | Z22: 2.83842 | AA22: 2.8458 | AB22: 2.85165 | AC22: 2.85768 | AD22: 2.86212 | AE22: 2.86597 | AF22: 2.86872 | AG22: 2.87345
A23: Retiring Components Potential Energy Use Summed Across Fuels[rural residential,cooling and ventilation] : MostRecentRun | B23: 74.6063 | C23: 74.6063 | D23: 74.6063 | E23: 74.6063 | F23: 74.6063 | G23: 74.6063 | H23: 74.6063 | I23: 74.6063 | J23: 74.6063 | K23: 74.6063 | L23: 74.6063 | M23: 74.6063 | N23: 74.6063 | O23: 74.6063 | P23: 74.6063 | Q23: 74.6063 | R23: 70.3724 | S23: 66.971 | T23: 63.8569 | U23: 60.9422 | V23: 58.3175 | W23: 55.9782 | X23: 53.8007 | Y23: 52.101 | Z23: 50.6779 | AA23: 49.524 | AB23: 48.6304 | AC23: 47.9514 | AD23: 47.2975 | AE23: 46.8686 | AF23: 46.4992 | AG23: 46.1634
A24: Retiring Components Potential Energy Use Summed Across Fuels[rural residential,envelope] : MostRecentRun | B24: 0 | C24: 0 | D24: 0 | E24: 0 | F24: 0 | G24: 0 | H24: 0 | I24: 0 | J24: 0 | K24: 0 | L24: 0 | M24: 0 | N24: 0 | O24: 0 | P24: 0 | Q24: 0 | R24: 0 | S24: 0 | T24: 0 | U24: 0 | V24: 0 | W24: 0 | X24: 0 | Y24: 0 | Z24: 0 | AA24: 0 | AB24: 0 | AC24: 0 | AD24: 0 | AE24: 0 | AF24: 0 | AG24: 0
A25: Retiring Components Potential Energy Use Summed Across Fuels[rural residential,lighting] : MostRecentRun | B25: 181.799 | C25: 181.799 | D25: 181.799 | E25: 181.799 | F25: 181.799 | G25: 181.799 | H25: 181.799 | I25: 181.799 | J25: 181.799 | K25: 181.799 | L25: 159.528 | M25: 155.263 | N25: 152.182 | O25: 149.191 | P25: 146.366 | Q25: 144.446 | R25: 143.404 | S25: 142.599 | T25: 141.661 | U25: 140.734 | V25: 139.912 | W25: 139.414 | X25: 139.223 | Y25: 139.129 | Z25: 138.922 | AA25: 138.607 | AB25: 137.787 | AC25: 136.816 | AD25: 135.734 | AE25: 134.616 | AF25: 133.512 | AG25: 130.955
A26: Retiring Components Potential Energy Use Summed Across Fuels[rural residential,appliances] : MostRecentRun | B26: 1.39423 | C26: 1.39423 | D26: 1.39423 | E26: 1.39423 | F26: 1.39423 | G26: 1.39423 | H26: 1.39423 | I26: 1.39423 | J26: 1.39423 | K26: 1.39423 | L26: 1.39423 | M26: 1.39423 | N26: 1.39423 | O26: 1.39423 | P26: 1.16985 | Q26: 1.16032 | R26: 1.15161 | S26: 1.14319 | T26: 1.13588 | U26: 1.12977 | V26: 1.12522 | W26: 1.12287 | X26: 1.12201 | Y26: 1.12267 | Z26: 1.12451 | AA26: 1.12798 | AB26: 1.13236 | AC26: 1.13777 | AD26: 1.14309 | AE26: 1.14915 | AF26: 1.1553 | AG26: 1.16211
... A33: Retiring Components Potential Energy Use Summed Across Fuels[commercial,other component] : MostRecentRun | B33: 4.07131 | C33: 4.07131 | D33: 4.07131 | E33: 4.07131 | F33: 4.07131 | G33: 4.07131 | H33: 4.07131 | I33: 4.07131 | J33: 4.07131 | K33: 4.07131 | L33: 4.07131 | M33: 4.07131 | N33: 4.07131 | O33: 4.07131 | P33: 4.07131 | Q33: 4.07131 | R33: 4.36156 | S33: 4.36179 | T33: 4.40102 | U33: 4.45525 | V33: 4.51922 | W33: 4.58474 | X33: 4.65651 | Y33: 4.72896 | Z33: 4.80672 | AA33: 4.89033 | AB33: 4.97855 | AC33: 5.0685 | AD33: 5.16242 | AE33: 5.26021 | AF33: 5.3597 | AG33: 5.45881
A34: Calculated yearly change percentage
A35: Retiring Components Potential Energy Use Summed Across Fuels[urban residential,heating] : MostRecentRun | C35: =(C16-B16)/C16 | D35: =(D16-C16)/D16 | E35: =(E16-D16)/E16 | F35: =(F16-E16)/F16 | G35: =(G16-F16)/G16 | H35: =(H16-G16)/H16 | I35: =(I16-H16)/I16 | J35: =(J16-I16)/J16 | ... AG35: =(AG16-AF16)/AG16
A36: Retiring Components Potential Energy Use Summed Across Fuels[urban residential,cooling and ventilation] : MostRecentRun | C36: =(C17-B17)/C17 | D36: =(D17-C17)/D17 | E36: =(E17-D17)/E17 | F36: =(F17-E17)/F17 | G36: =(G17-F17)/G17 | H36: =(H17-G17)/H17 | I36: =(I17-H17)/I17 | J36: =(J17-I17)/J17 | ... AG36: =(AG17-AF17)/AG17
A37: Retiring Components Potential Energy Use Summed Across Fuels[urban residential,envelope] : MostRecentRun | C37: 0 | D37: 0 | E37: 0 | F37: 0 | G37: 0 | H37: 0 | I37: 0 | J37: 0 | K37: 0 | L37: 0 | M37: 0 | N37: 0 | O37: 0 | P37: 0 | Q37: 0 | R37: 0 | S37: 0 | T37: 0 | U37: 0 | V37: 0 | W37: 0 | X37: 0 | Y37: 0 | Z37: 0 | AA37: 0 | AB37: 0 | AC37: 0 | AD37: 0 | AE37: 0 | AF37: 0 | AG37: 0
A38: Retiring Components Potential Energy Use Summed Across Fuels[urban residential,lighting] : MostRecentRun | C38: =(C19-B19)/C19 | D38: =(D19-C19)/D19 | E38: =(E19-D19)/E19 | F38: =(F19-E19)/F19 | G38: =(G19-F19)/G19 | H38: =(H19-G19)/H19 | I38: =(I19-H19)/I19 | J38: =(J19-I19)/J19 | ... AG38: =(AG19-AF19)/AG19
A39: Retiring Components Potential Energy Use Summed Across Fuels[urban residential,appliances] : MostRecentRun | C39: =(C20-B20)/C20 | D39: =(D20-C20)/D20 | E39: =(E20-D20)/E20 | F39: =(F20-E20)/F20 | G39: =(G20-F20)/G20 | H39: =(H20-G20)/H20 | I39: =(I20-H20)/I20 | J39: =(J20-I20)/J20 | ... AG39: =(AG20-AF20)/AG20
A40: Retiring Components Potential Energy Use Summed Across Fuels[urban residential,other component] : MostRecentRun | C40: =(C21-B21)/C21 | D40: =(D21-C21)/D21 | E40: =(E21-D21)/E21 | F40: =(F21-E21)/F21 | G40: =(G21-F21)/G21 | H40: =(H21-G21)/H21 | I40: =(I21-H21)/I21 | J40: =(J21-I21)/J21 | ... AG40: =(AG21-AF21)/AG21
A41: Retiring Components Potential Energy Use Summed Across Fuels[rural residential,heating] : MostRecentRun | C41: =(C22-B22)/C22 | D41: =(D22-C22)/D22 | E41: =(E22-D22)/E22 | F41: =(F22-E22)/F22 | G41: =(G22-F22)/G22 | H41: =(H22-G22)/H22 | I41: =(I22-H22)/I22 | J41: =(J22-I22)/J22 | ... AG41: =(AG22-AF22)/AG22
A42: Retiring Components Potential Energy Use Summed Across Fuels[rural residential,cooling and ventilation] : MostRecentRun | C42: =(C23-B23)/C23 | D42: =(D23-C23)/D23 | E42: =(E23-D23)/E23 | F42: =(F23-E23)/F23 | G42: =(G23-F23)/G23 | H42: =(H23-G23)/H23 | I42: =(I23-H23)/I23 | J42: =(J23-I23)/J23 | ... AG42: =(AG23-AF23)/AG23
A43: Retiring Components Potential Energy Use Summed Across Fuels[rural residential,envelope] : MostRecentRun | C43: 0 | D43: 0 | E43: 0 | F43: 0 | G43: 0 | H43: 0 | I43: 0 | J43: 0 | K43: 0 | L43: 0 | M43: 0 | N43: 0 | O43: 0 | P43: 0 | Q43: 0 | R43: 0 | S43: 0 | T43: 0 | U43: 0 | V43: 0 | W43: 0 | X43: 0 | Y43: 0 | Z43: 0 | AA43: 0 | AB43: 0 | AC43: 0 | AD43: 0 | AE43: 0 | AF43: 0 | AG43: 0
A44: Retiring Components Potential Energy Use Summed Across Fuels[rural residential,lighting] : MostRecentRun | C44: =(C25-B25)/C25 | D44: =(D25-C25)/D25 | E44: =(E25-D25)/E25 | F44: =(F25-E25)/F25 | G44: =(G25-F25)/G25 | H44: =(H25-G25)/H25 | I44: =(I25-H25)/I25 | J44: =(J25-I25)/J25 | ... AG44: =(AG25-AF25)/AG25
A45: Retiring Components Potential Energy Use Summed Across Fuels[rural residential,appliances] : MostRecentRun | C45: =(C26-B26)/C26 | D45: =(D26-C26)/D26 | E45: =(E26-D26)/E26 | F45: =(F26-E26)/F26 | G45: =(G26-F26)/G26 | H45: =(H26-G26)/H26 | I45: =(I26-H26)/I26 | J45: =(J26-I26)/J26 | ... AG45: =(AG26-AF26)/AG26
A46: Retiring Components Potential Energy Use Summed Across Fuels[rural residential,other component] : MostRecentRun | C46: =(C27-B27)/C27 | D46: =(D27-C27)/D27 | E46: =(E27-D27)/E27 | F46: =(F27-E27)/F27 | G46: =(G27-F27)/G27 | H46: =(H27-G27)/H27 | I46: =(I27-H27)/I27 | J46: =(J27-I27)/J27 | ... AG46: =(AG27-AF27)/AG27
A47: Retiring Components Potential Energy Use Summed Across Fuels[commercial,heating] : MostRecentRun | C47: =(C28-B28)/C28 | D47: =(D28-C28)/D28 | E47: =(E28-D28)/E28 | F47: =(F28-E28)/F28 | G47: =(G28-F28)/G28 | H47: =(H28-G28)/H28 | I47: =(I28-H28)/I28 | J47: =(J28-I28)/J28 | ... AG47: =(AG28-AF28)/AG28
A48: Retiring Components Potential Energy Use Summed Across Fuels[commercial,cooling and ventilation] : MostRecentRun | C48: =(C29-B29)/C29 | D48: =(D29-C29)/D29 | E48: =(E29-D29)/E29 | F48: =(F29-E29)/F29 | G48: =(G29-F29)/G29 | H48: =(H29-G29)/H29 | I48: =(I29-H29)/I29 | J48: =(J29-I29)/J29 | ... AG48: =(AG29-AF29)/AG29
A49: Retiring Components Potential Energy Use Summed Across Fuels[commercial,envelope] : MostRecentRun | C49: 0 | D49: 0 | E49: 0 | F49: 0 | G49: 0 | H49: 0 | I49: 0 | J49: 0 | K49: 0 | L49: 0 | M49: 0 | N49: 0 | O49: 0 | P49: 0 | Q49: 0 | R49: 0 | S49: 0 | T49: 0 | U49: 0 | V49: 0 | W49: 0 | X49: 0 | Y49: 0 | Z49: 0 | AA49: 0 | AB49: 0 | AC49: 0 | AD49: 0 | AE49: 0 | AF49: 0 | AG49: 0
A50: Retiring Components Potential Energy Use Summed Across Fuels[commercial,lighting] : MostRecentRun | C50: =(C31-B31)/C31 | D50: =(D31-C31)/D31 | E50: =(E31-D31)/E31 | F50: =(F31-E31)/F31 | G50: =(G31-F31)/G31 | H50: =(H31-G31)/H31 | I50: =(I31-H31)/I31 | J50: =(J31-I31)/J31 | ... AG50: =(AG31-AF31)/AG31
A51: Retiring Components Potential Energy Use Summed Across Fuels[commercial,appliances] : MostRecentRun | C51: =(C32-B32)/C32 | D51: =(D32-C32)/D32 | E51: =(E32-D32)/E32 | F51: =(F32-E32)/F32 | G51: =(G32-F32)/G32 | H51: =(H32-G32)/H32 | I51: =(I32-H32)/I32 | J51: =(J32-I32)/J32 | ... AG51: =(AG32-AF32)/AG32
...

Sheet Component Lifetimes
A1: Building Component | B1: Lifetime (yr)
A2: heating | B2: 19
A3: cooling and ventilation | B3: 15.833333
A4: envelope | B4: 51.818182
A5: lighting | B5: 9.1324201
A6: appliances | B6: 13.533333
A7: other component | B7: 15.4

Sheet AEO T4
B1: ref2017.d120816a | C1: 2015 | D1: 2016 | E1: 2017 | F1: 2018 | G1: 2019 | H1: 2020 | I1: 2021 | J1: 2022 | K1: 2023 | L1: 2024 | M1: 2025 | N1: 2026 | O1: 2027 | P1: 2028 | Q1: 2029 | R1: 2030 | S1: 2031 | T1: 2032 | U1: 2033 | V1: 2034 | W1: 2035 | X1: 2036 | Y1: 2037 | Z1: 2038 | AA1: 2039 | AB1: 2040 | AC1: 2041 | AD1: 2042 | AE1: 2043 | AF1: 2044 | AG1: 2045 | AH1: 2046 | AI1: 2047 | AJ1: 2048 | AK1: 2049 | AL1: 2050
C3: Report | D3: Annual Energy Outlook 2017
C4: Scenario | D4: ref2017 | G4: Reference case
C5: Datekey | D5: d120816a
C6: Release Date | E6: January 2017
A10: RKI000 | B10: 4. Residential Sector Key Indicators and Consumption
B11: (quadrillion Btu, unless otherwise noted)
AM12: 2016-
B13: Key Indicators and Consumption | C13: 2015 | D13: 2016 | E13: 2017 | F13: 2018 | G13: 2019 | H13: 2020 | I13: 2021 | J13: 2022 | K13: 2023 | L13: 2024 | M13: 2025 | N13: 2026 | O13: 2027 | P13: 2028 | Q13: 2029 | R13: 2030 | S13: 2031 | T13: 2032 | U13: 2033 | V13: 2034 | W13: 2035 | X13: 2036 | Y13: 2037 | Z13: 2038 | AA13: 2039 | AB13: 2040 | AC13: 2041 | AD13: 2042 | AE13: 2043 | AF13: 2044 | AG13: 2045 | AH13: 2046 | AI13: 2047 | AJ13: 2048 | AK13: 2049 | AL13: 2050 | AM13: 2050
B15: Key Indicators
B16: Households (millions)
A17: RKI000:ba_Single-Family | B17: Single-Family | C17: 80.548882 | D17: 81.10302 | E17: 81.82338 | F17: 82.645271 | G17: 83.465591 | H17: 84.301651 | I17: 85.147186 | J17: 86.01313 | K17: 86.889809 | L17: 87.77227 | M17: 88.648026 | N17: 89.503479 | O17: 90.324585 | P17: 91.099731 | Q17: 91.856583 | R17: 92.619987 | S17: 93.361687 | T17: 94.051025 | U17: 94.733063 | V17: 95.449333 | W17: 96.199455 | X17: 96.957245 | Y17: 97.713737 | Z17: 98.475151 | AA17: 99.23101 | AB17: 99.989937 | AC17: 100.75047 | AD17: 101.50308 | AE17: 102.26664 | AF17: 103.0535 | AG17: 103.86337 | AH17: 104.68725 | AI17: 105.51291 | AJ17: 106.32539 | AK17: 107.12827 | AL17: 107.92848 | AM17: 0.00844
A18: RKI000:ba_Multifamily | B18: Multifamily | C18: 28.870884 | D18: 29.110094 | E18: 29.380239 | F18: 29.680817 | G18: 30.01416 | H18: 30.373581 | I18: 30.756231 | J18: 31.153685 | K18: 31.553375 | L18: 31.957239 | M18: 32.351425 | N18: 32.732346 | O18: 33.110371 | P18: 33.49255 | Q18: 33.875225 | R18: 34.257374 | S18: 34.636684 | T18: 35.013767 | U18: 35.396408 | V18: 35.785557 | W18: 36.181156 | X18: 36.573303 | Y18: 36.961632 | Z18: 37.346928 | AA18: 37.722347 | AB18: 38.090382 | AC18: 38.449062 | AD18: 38.806965 | AE18: 39.162479 | AF18: 39.514824 | AG18: 39.860397 | AH18: 40.201298 | AI18: 40.538223 | AJ18: 40.868778 | AK18: 41.197083 | AL18: 41.520844 | AM18: 0.010499
A19: RKI000:ba_MobileHomes | B19: Mobile Homes | C19: 5.965145 | D19: 5.842867 | E19: 5.742257 | F19: 5.664587 | G19: 5.591901 | H19: 5.524901 | I19: 5.472419 | J19: 5.436611 | K19: 5.408078 | L19: 5.385289 | M19: 5.3637 | N19: 5.333962 | O19: 5.294229 | P19: 5.248191 | Q19: 5.200993 | R19: 5.152752 | S19: 5.102839 | T19: 5.051295 | U19: 5.002883 | V19: 4.961352 | W19: 4.926433 | X19: 4.895687 | Y19: 4.867416 | Z19: 4.845345 | AA19: 4.827591 | AB19: 4.811014 | AC19: 4.794406 | AD19: 4.778117 | AE19: 4.760415 | AF19: 4.740447 | AG19: 4.715725 | AH19: 4.68894 | AI19: 4.660537 | AJ19: 4.629189 | AK19: 4.597032 | AL19: 4.56343 | AM19: -0.007243
A20: RKI000:ba_Total | B20: Total | C20: 115.38492 | D20: 116.05598 | E20: 116.94588 | F20: 117.99068 | G20: 119.07166 | H20: 120.20013 | I20: 121.37584 | J20: 122.60342 | K20: 123.85126 | L20: 125.1148 | M20: 126.36315 | N20: 127.56979 | O20: 128.72919 | P20: 129.84047 | Q20: 130.9328 | R20: 132.03012 | S20: 133.10121 | T20: 134.11609 | U20: 135.13235 | V20: 136.19624 | W20: 137.30705 | X20: 138.42624 | Y20: 139.54279 | Z20: 140.66744 | AA20: 141.78095 | AB20: 142.89134 | AC20: 143.99393 | AD20: 145.08817 | AE20: 146.18955 | AF20: 147.30878 | AG20: 148.43948 | AH20: 149.57748 | AI20: 150.71167 | AJ20: 151.82336 | AK20: 152.92238 | AL20: 154.01276 | AM20: 0.008357
A22: RKI000:ca_AverageHouseS | B22: Average House Square Footage | C22: 1695.0878 | D22: 1703.2651 | E22: 1711.6783 | F22: 1720.0626 | G22: 1728.099 | H22: 1735.8943 | I22: 1743.3932 | J22: 1750.6895 | K22: 1757.9084 | L22: 1765.0195 | M22: 1772.1107 | N22: 1779.2067 | O22: 1786.1916 | P22: 1792.9419 | Q22: 1799.5736 | R22: 1806.2012 | S22: 1812.7317 | T22: 1819.0262 | U22: 1825.199 | V22: 1831.3966 | W22: 1837.626 | X22: 1843.8593 | Y22: 1850.0693 | Z22: 1856.2556 | AA22: 1862.4346 | AB22: 1868.646 | AC22: 1874.9025 | AD22: 1881.1038 | AE22: 1887.3536 | AF22: 1893.7168 | AG22: 1900.2357 | AH22: 1906.8367 | AI22: 1913.4568 | AJ22: 1920.0542 | AK22: 1926.6034 | AL22: 1933.1583 | AM22: 0.003731
B24: Energy Intensity
B25: (million Btu per household)
A26: RKI000:da_DeliveredEner | B26: Delivered Energy Consumption | C26: 95.092171 | D26: 91.514305 | E26: 93.235954 | F26: 93.20533 | G26: 92.119431 | H26: 90.596268 | I26: 89.305229 | J26: 88.062706 | K26: 86.945023 | L26: 85.989021 | M26: 85.068665 | N26: 84.170921 | O26: 83.288025 | P26: 82.493507 | Q26: 81.758041 | R26: 81.003342 | S26: 80.306366 | T26: 79.661469 | U26: 79.07061 | V26: 78.507645 | W26: 77.900688 | X26: 77.31575 | Y26: 76.757065 | Z26: 76.239441 | AA26: 75.742729 | AB26: 75.246231 | AC26: 74.741257 | AD26: 74.238434 | AE26: 73.729492 | AF26: 73.223419 | AG26: 72.72551 | AH26: 72.229294 | AI26: 71.727997 | AJ26: 71.198563 | AK26: 70.677345 | AL26: 70.151375 | AM26: -0.007788
A27: RKI000:da_TotalEnergyCo | B27: Total Energy Consumption | C27: 178.03015 | D27: 172.3932 | E27: 173.36307 | F27: 172.74106 | G27: 171.11243 | H27: 168.35864 | I27: 165.76492 | J27: 163.26141 | K27: 161.14697 | L27: 159.12972 | M27: 157.0602 | N27: 154.86238 | O27: 153.01291 | P27: 151.35422 | Q27: 149.92725 | R27: 148.44684 | S27: 147.19064 | T27: 145.94107 | U27: 145.06276 | V27: 143.89093 | W27: 142.56427 | X27: 141.70538 | Y27: 140.52081 | Z27: 139.61462 | AA27: 138.74222 | AB27: 137.95392 | AC27: 137.00166 | AD27: 136.08182 | AE27: 135.21374 | AF27: 134.20184 | AG27: 133.0312 | AH27: 131.96632 | AI27: 130.84097 | AJ27: 129.76594 | AK27: 128.76866 | AL27: 127.43207 | AM27: -0.008849
B28: (thousand Btu per square foot)
A29: RKI000:ea_DeliveredEner | B29: Delivered Energy Consumption | C29: 56.098671 | D29: 53.728748 | E29: 54.470486 | F29: 54.187172 | G29: 53.306805 | H29: 52.189968 | I29: 51.224949 | J29: 50.301727 | K29: 49.459358 | L29: 48.718452 | M29: 48.004147 | N29: 47.308121 | O29: 46.62883 | P29: 46.010139 | Q29: 45.431896 | R29: 44.847355 | S29: 44.301296 | T29: 43.793468 | U29: 43.32164 | V29: 42.867638 | W29: 42.392025 | X29: 41.93148 | Y29: 41.48875 | Z29: 41.071629 | AA29: 40.668667 | AB29: 40.267784 | AC29: 39.864079 | AD29: 39.465355 | AE29: 39.06501 | AF29: 38.666508 | AG29: 38.271835 | AH29: 37.87912 | AI29: 37.48608 | AJ29: 37.081539 | AK29: 36.684948 | AL29: 36.288479 | AM29: -0.011476
A30: RKI000:ea_TotalEnergyCo | B30: Total Energy Consumption | C30: 105.0271 | D30: 101.21337 | E30: 101.2825 | F30: 100.42718 | G30: 99.017723 | H30: 96.986687 | I30: 95.081779 | J30: 93.255501 | K30: 91.669716 | L30: 90.157478 | M30: 88.628883 | N30: 87.040131 | O30: 85.66433 | P30: 84.416687 | Q30: 83.312653 | R30: 82.187325 | S30: 81.19825 | T30: 80.230324 | U30: 79.477783 | V30: 78.568962 | W30: 77.580673 | X30: 76.852608 | Y30: 75.954346 | Z30: 75.213036 | AA30: 74.495087 | AB30: 73.825607 | AC30: 73.07135 | AD30: 72.341469 | AE30: 71.641975 | AF30: 70.866905 | AG30: 70.007744 | AH30: 69.20694 | AI30: 68.379372 | AJ30: 67.584518 | AK30: 66.837143 | AL30: 65.919106 | AM30: -0.012533
B32: Delivered Energy Consumption by Fuel
B33: Purchased Electricity
A34: RKI000:fa_SpaceHeating | B34: Space Heating | C34: 0.331095 | D34: 0.327905 | E34: 0.349864 | F34: 0.360698 | G34: 0.359427 | H34: 0.35678 | I34: 0.354556 | J34: 0.351704 | K34: 0.349147 | L34: 0.347889 | M34: 0.346378 | N34: 0.344521 | O34: 0.342983 | P34: 0.341653 | Q34: 0.340396 | R34: 0.339176 | S34: 0.337991 | T34: 0.336796 | U34: 0.335669 | V34: 0.334739 | W34: 0.333526 | X34: 0.332407 | Y34: 0.331335 | Z34: 0.330215 | AA34: 0.329147 | AB34: 0.328134 | AC34: 0.327134 | AD34: 0.32601 | AE34: 0.324843 | AF34: 0.323649 | AG34: 0.322493 | AH34: 0.321251 | AI34: 0.320117 | AJ34: 0.318898 | AK34: 0.31769 | AL34: 0.3165 | AM34: -0.001041
A35: RKI000:fa_SpaceCooling | B35: Space Cooling | C35: 0.794241 | D35: 0.843365 | E35: 0.734594 | F35: 0.76137 | G35: 0.762741 | H35: 0.761492 | I35: 0.761669 | J35: 0.760511 | K35: 0.760795 | L35: 0.763733 | M35: 0.766355 | N35: 0.769149 | O35: 0.772869 | P35: 0.777587 | Q35: 0.782814 | R35: 0.787987 | S35: 0.794111 | T35: 0.799816 | U35: 0.805894 | V35: 0.812054 | W35: 0.81797 | X35: 0.823585 | Y35: 0.828776 | Z35: 0.834249 | AA35: 0.839338 | AB35: 0.843899 | AC35: 0.848227 | AD35: 0.852276 | AE35: 0.855443 | AF35: 0.858159 | AG35: 0.860597 | AH35: 0.862771 | AI35: 0.864408 | AJ35: 0.86468 | AK35: 0.864275 | AL35: 0.863426 | AM35: 0.000692
A36: RKI000:fa_WaterHeating | B36: Water Heating | C36: 0.450959 | D36: 0.455588 | E36: 0.459874 | F36: 0.463842 | G36: 0.466237 | H36: 0.466061 | I36: 0.466631 | J36: 0.466397 | K36: 0.466415 | L36: 0.467595 | M36: 0.468658 | N36: 0.46926 | O36: 0.470007 | P36: 0.470921 | Q36: 0.471731 | R36: 0.472078 | S36: 0.472246 | T36: 0.472215 | U36: 0.471744 | V36: 0.470985 | W36: 0.469734 | X36: 0.468383 | Y36: 0.467286 | Z36: 0.466714 | AA36: 0.466841 | AB36: 0.467631 | AC36: 0.46911 | AD36: 0.470964 | AE36: 0.472968 | AF36: 0.475037 | AG36: 0.477081 | AH36: 0.479117 | AI36: 0.481072 | AJ36: 0.482834 | AK36: 0.484493 | AL36: 0.486022 | AM36: 0.001904
A37: RKI000:fa_Refrigeration | B37: Refrigeration | C37: 0.355201 | D37: 0.35081 | E37: 0.346875 | F37: 0.343662 | G37: 0.340835 | H37: 0.338432 | I37: 0.336455 | J37: 0.334212 | K37: 0.332347 | L37: 0.330892 | M37: 0.329846 | N37: 0.329135 | O37: 0.328747 | P37: 0.328678 | Q37: 0.329 | R37: 0.32979 | S37: 0.330945 | T37: 0.332402 | U37: 0.334299 | V37: 0.336792 | W37: 0.339898 | X37: 0.343507 | Y37: 0.347132 | Z37: 0.350793 | AA37: 0.354434 | AB37: 0.358071 | AC37: 0.361684 | AD37: 0.365255 | AE37: 0.368825 | AF37: 0.37242 | AG37: 0.376024 | AH37: 0.379613 | AI37: 0.383152 | AJ37: 0.386586 | AK37: 0.389937 | AL37: 0.39322 | AM37: 0.003362
A38: RKI000:fa_Cooking | B38: Cooking | C38: 0.107912 | D38: 0.108876 | E38: 0.110093 | F38: 0.111487 | G38: 0.112918 | H38: 0.1144 | I38: 0.115934 | J38: 0.117524 | K38: 0.119134 | L38: 0.120757 | M38: 0.122359 | N38: 0.123909 | O38: 0.1254 | P38: 0.126833 | Q38: 0.128242 | R38: 0.129656 | S38: 0.131037 | T38: 0.132353 | U38: 0.133671 | V38: 0.135043 | W38: 0.13647 | X38: 0.137907 | Y38: 0.13934 | Z38: 0.140783 | AA38: 0.142213 | AB38: 0.143639 | AC38: 0.145055 | AD38: 0.146462 | AE38: 0.147877 | AF38: 0.149312 | AG38: 0.150759 | AH38: 0.152214 | AI38: 0.153665 | AJ38: 0.155088 | AK38: 0.156497 | AL38: 0.157896 | AM38: 0.010993
A39: RKI000:fa_ClothesDryers | B39: Clothes Dryers | C39: 0.204635 | D39: 0.206883 | E39: 0.209296 | F39: 0.212039 | G39: 0.214057 | H39: 0.215143 | I39: 0.216217 | J39: 0.21703 | K39: 0.218042 | L39: 0.219747 | M39: 0.221473 | N39: 0.223056 | O39: 0.224778 | P39: 0.226697 | Q39: 0.228736 | R39: 0.230917 | S39: 0.233149 | T39: 0.235399 | U39: 0.23778 | V39: 0.24031 | W39: 0.242833 | X39: 0.245391 | Y39: 0.248003 | Z39: 0.250667 | AA39: 0.253331 | AB39: 0.256003 | AC39: 0.258678 | AD39: 0.261266 | AE39: 0.263761 | AF39: 0.266211 | AG39: 0.268628 | AH39: 0.271044 | AI39: 0.273422 | AJ39: 0.275691 | AK39: 0.277913 | AL39: 0.280083 | AM39: 0.00895
A40: RKI000:fa_Freezers | B40: Freezers | C40: 0.07543 | D40: 0.074619 | E40: 0.073888 | F40: 0.073192 | G40: 0.072462 | H40: 0.071706 | I40: 0.070935 | J40: 0.070168 | K40: 0.069453 | L40: 0.068787 | M40: 0.068159 | N40: 0.067552 | O40: 0.066966 | P40: 0.0664 | Q40: 0.065872 | R40: 0.065407 | S40: 0.064986 | T40: 0.064596 | U40: 0.064264 | V40: 0.064015 | W40: 0.063865 | X40: 0.063791 | Y40: 0.0638 | Z40: 0.063906 | AA40: 0.064104 | AB40: 0.064395 | AC40: 0.064768 | AD40: 0.065146 | AE40: 0.065538 | AF40: 0.065951 | AG40: 0.066383 | AH40: 0.06683 | AI40: 0.067283 | AJ40: 0.067733 | AK40: 0.068182 | AL40: 0.068633 | AM40: -0.002456
A41: RKI000:fa_Lighting | B41: Lighting | C41: 0.448123 | D41: 0.441566 | E41: 0.435892 | F41: 0.434207 | G41: 0.424534 | H41: 0.373465 | I41: 0.342323 | J41: 0.318797 | K41: 0.303977 | L41: 0.294402 | M41: 0.287885 | N41: 0.282972 | O41: 0.279133 | P41: 0.276178 | Q41: 0.273961 | R41: 0.264825 | S41: 0.25764 | T41: 0.252522 | U41: 0.249772 | V41: 0.249398 | W41: 0.249332 | X41: 0.249677 | Y41: 0.250358 | Z41: 0.251256 | AA41: 0.252238 | AB41: 0.248426 | AC41: 0.245436 | AD41: 0.243001 | AE41: 0.241185 | AF41: 0.240336 | AG41: 0.240358 | AH41: 0.2406 | AI41: 0.240962 | AJ41: 0.241355 | AK41: 0.241794 | AL41: 0.242266 | AM41: -0.017501
A42: RKI000:fa_ClothesWasher | B42: Clothes Washers 1/ | C42: 0.026497 | D42: 0.025667 | E42: 0.024887 | F42: 0.023776 | G42: 0.02266 | H42: 0.021433 | I42: 0.020162 | J42: 0.019082 | K42: 0.018184 | L42: 0.017458 | M42: 0.016899 | N42: 0.016508 | O42: 0.016292 | P42: 0.016259 | Q42: 0.016195 | R42: 0.016114 | S42: 0.01603 | T42: 0.015958 | U42: 0.015923 | V42: 0.015941 | W42: 0.016011 | X42: 0.016119 | Y42: 0.016252 | Z42: 0.0164 | AA42: 0.016553 | AB42: 0.016707 | AC42: 0.016862 | AD42: 0.017015 | AE42: 0.01717 | AF42: 0.017327 | AG42: 0.017485 | AH42: 0.017645 | AI42: 0.017804 | AJ42: 0.01796 | AK42: 0.018114 | AL42: 0.018267 | AM42: -0.009953
A43: RKI000:fa_Dishwashers | B43: Dishwashers 1/ | C43: 0.094424 | D43: 0.094505 | E43: 0.094796 | F43: 0.095229 | G43: 0.095648 | H43: 0.096045 | I43: 0.09644 | J43: 0.097098 | K43: 0.098031 | L43: 0.099282 | M43: 0.100798 | N43: 0.102534 | O43: 0.104483 | P43: 0.106602 | Q43: 0.108585 | R43: 0.110437 | S43: 0.112132 | T43: 0.11367 | U43: 0.115158 | V43: 0.116683 | W43: 0.118256 | X43: 0.119853 | Y43: 0.121467 | Z43: 0.123111 | AA43: 0.124761 | AB43: 0.126427 | AC43: 0.128099 | AD43: 0.129763 | AE43: 0.13143 | AF43: 0.133109 | AG43: 0.134785 | AH43: 0.136453 | AI43: 0.138095 | AJ43: 0.139687 | AK43: 0.141238 | AL43: 0.142754 | AM43: 0.012205
A44: RKI000:fa_ColorTelevisi | B44: Televisions and Related Equipment 2/ | C44: 0.288212 | D44: 0.282494 | E44: 0.2774 | F44: 0.273162 | G44: 0.26852 | H44: 0.263822 | I44: 0.259875 | J44: 0.256199 | K44: 0.253304 | L44: 0.251986 | M44: 0.251491 | N44: 0.251538 | O44: 0.252468 | P44: 0.25441 | Q44: 0.257082 | R44: 0.260393 | S44: 0.264374 | T44: 0.268873 | U44: 0.273967 | V44: 0.279572 | W44: 0.285348 | X44: 0.291337 | Y44: 0.297421 | Z44: 0.303437 | AA44: 0.309231 | AB44: 0.314683 | AC44: 0.317851 | AD44: 0.320415 | AE44: 0.322613 | AF44: 0.324784 | AG44: 0.326932 | AH44: 0.329083 | AI44: 0.331172 | AJ44: 0.333129 | AK44: 0.335039 | AL44: 0.336865 | AM44: 0.005191
A45: RKI000:fa_PersonalCompu | B45: Computers and Related Equipment 3/ | C45: 0.111117 | D45: 0.107827 | E45: 0.104646 | F45: 0.101712 | G45: 0.098496 | H45: 0.095143 | I45: 0.091913 | J45: 0.088654 | K45: 0.085554 | L45: 0.082878 | M45: 0.08035 | N45: 0.077899 | O45: 0.07563 | P45: 0.073536 | Q45: 0.071573 | R45: 0.069687 | S45: 0.067884 | T45: 0.066139 | U45: 0.064451 | V45: 0.062801 | W45: 0.06113 | X45: 0.059417 | Y45: 0.057759 | Z45: 0.056146 | AA45: 0.054541 | AB45: 0.052936 | AC45: 0.051434 | AD45: 0.049901 | AE45: 0.048327 | AF45: 0.046734 | AG45: 0.045077 | AH45: 0.043361 | AI45: 0.041551 | AJ45: 0.039626 | AK45: 0.03757 | AL45: 0.035389 | AM45: -0.032238
... A48: RKI000:fa_DeliveredEner | B48: Delivered Energy | C48: 4.776403 | D48: 4.810625 | E48: 4.780662 | F48: 4.835242 | G48: 4.828907 | H48: 4.773632 | I48: 4.744377 | J48: 4.719576 | K48: 4.706628 | L48: 4.710382 | M48: 4.717607 | N48: 4.724288 | O48: 4.736067 | P48: 4.754208 | Q48: 4.773802 | R48: 4.784884 | S48: 4.799917 | T48: 4.817743 | U48: 4.841113 | V48: 4.869628 | W48: 4.898304 | X48: 4.927637 | Y48: 4.957467 | Z48: 4.989327 | AA48: 5.020275 | AB48: 5.045135 | AC48: 5.065891 | AD48: 5.086051 | AE48: 5.104714 | AF48: 5.122814 | AG48: 5.140799 | AH48: 5.157453 | AI48: 5.17076 | AJ48: 5.179155 | AK48: 5.18572 | AL48: 5.189838 | AM48: 0.002234
B50: Natural Gas
A51: RKI000:ga_SpaceHeating | B51: Space Heating | C51: 3.018605 | D51: 2.81811 | E51: 3.022673 | F51: 3.069636 | G51: 3.05641 | H51: 3.045718 | I51: 3.036772 | J51: 3.030123 | K51: 3.024146 | L51: 3.018647 | M51: 3.01191 | N51: 3.003914 | O51: 2.991818 | P51: 2.979888 | Q51: 2.969606 | R51: 2.962548 | S51: 2.956111 | T51: 2.949076 | U51: 2.943504 | V51: 2.938931 | W51: 2.931776 | X51: 2.925297 | Y51: 2.919778 | Z51: 2.915329 | AA51: 2.910455 | AB51: 2.906943 | AC51: 2.902937 | AD51: 2.897179 | AE51: 2.890561 | AF51: 2.884018 | AG51: 2.877572 | AH51: 2.871458 | AI51: 2.865892 | AJ51: 2.859157 | AK51: 2.853049 | AL51: 2.846776 | AM51: 0.000298
...

Sheet AEO T5
B1: ref2017.d120816a | C1: 2015 | D1: 2016 | E1: 2017 | F1: 2018 | G1: 2019 | H1: 2020 | I1: 2021 | J1: 2022 | K1: 2023 | L1: 2024 | M1: 2025 | N1: 2026 | O1: 2027 | P1: 2028 | Q1: 2029 | R1: 2030 | S1: 2031 | T1: 2032 | U1: 2033 | V1: 2034 | W1: 2035 | X1: 2036 | Y1: 2037 | Z1: 2038 | AA1: 2039 | AB1: 2040 | AC1: 2041 | AD1: 2042 | AE1: 2043 | AF1: 2044 | AG1: 2045 | AH1: 2046 | AI1: 2047 | AJ1: 2048 | AK1: 2049 | AL1: 2050
C3: Report | D3: Annual Energy Outlook 2017
C4: Scenario | D4: ref2017 | G4: Reference case
C5: Datekey | D5: d120816a
C6: Release Date | E6: January 2017
A10: CKI000 | B10: 5. Commercial Sector Key Indicators and Consumption
B11: (quadrillion Btu, unless otherwise noted)
AM12: 2016-
B13: Key Indicators and Consumption | C13: 2015 | D13: 2016 | E13: 2017 | F13: 2018 | G13: 2019 | H13: 2020 | I13: 2021 | J13: 2022 | K13: 2023 | L13: 2024 | M13: 2025 | N13: 2026 | O13: 2027 | P13: 2028 | Q13: 2029 | R13: 2030 | S13: 2031 | T13: 2032 | U13: 2033 | V13: 2034 | W13: 2035 | X13: 2036 | Y13: 2037 | Z13: 2038 | AA13: 2039 | AB13: 2040 | AC13: 2041 | AD13: 2042 | AE13: 2043 | AF13: 2044 | AG13: 2045 | AH13: 2046 | AI13: 2047 | AJ13: 2048 | AK13: 2049 | AL13: 2050 | AM13: 2050
B15: Key Indicators
B17: Total Floorspace (billion square feet)
A18: CKI000:da_Surviving | B18: Surviving | C18: 87.052673 | D18: 87.748482 | E18: 88.624725 | F18: 89.572952 | G18: 90.595345 | H18: 91.665276 | I18: 92.7369 | J18: 93.823814 | K18: 94.906044 | L18: 95.986115 | M18: 97.062828 | N18: 98.128677 | O18: 99.18222 | P18: 100.23046 | Q18: 101.28615 | R18: 102.34911 | S18: 103.41438 | T18: 104.48439 | U18: 105.55275 | V18: 106.62647 | W18: 107.7075 | X18: 108.78487 | Y18: 109.85697 | Z18: 110.92455 | AA18: 111.9983 | AB18: 113.07514 | AC18: 114.15466 | AD18: 115.23334 | AE18: 116.31342 | AF18: 117.39578 | AG18: 118.48219 | AH18: 119.57352 | AI18: 120.66897 | AJ18: 121.76048 | AK18: 122.84802 | AL18: 123.93219 | AM18: 0.010206
A19: CKI000:da_NewAdditions | B19: New Additions | C19: 1.806707 | D19: 1.995486 | E19: 2.075766 | F19: 2.158288 | G19: 2.214259 | H19: 2.224493 | I19: 2.248463 | J19: 2.25259 | K19: 2.259454 | L19: 2.265276 | M19: 2.263771 | N19: 2.261031 | O19: 2.265505 | P19: 2.282902 | Q19: 2.300351 | R19: 2.313028 | S19: 2.328386 | T19: 2.337556 | U19: 2.353944 | V19: 2.372502 | W19: 2.380299 | X19: 2.386698 | Y19: 2.394062 | Z19: 2.41226 | AA19: 2.42761 | AB19: 2.442725 | AC19: 2.454479 | AD19: 2.468655 | AE19: 2.483835 | AF19: 2.500962 | AG19: 2.519112 | AH19: 2.536558 | AI19: 2.546119 | AJ19: 2.555725 | AK19: 2.56608 | AL19: 2.579243 | AM19: 0.007576
A20: CKI000:da_Total | B20: Total | C20: 88.859383 | D20: 89.743965 | E20: 90.700493 | F20: 91.731239 | G20: 92.809601 | H20: 93.889771 | I20: 94.985367 | J20: 96.076401 | K20: 97.165497 | L20: 98.251389 | M20: 99.326599 | N20: 100.38971 | O20: 101.44772 | P20: 102.51337 | Q20: 103.5865 | R20: 104.66214 | S20: 105.74276 | T20: 106.82194 | U20: 107.90669 | V20: 108.99898 | W20: 110.0878 | X20: 111.17157 | Y20: 112.25103 | Z20: 113.33682 | AA20: 114.42591 | AB20: 115.51787 | AC20: 116.60913 | AD20: 117.702 | AE20: 118.79726 | AF20: 119.89674 | AG20: 121.0013 | AH20: 122.11008 | AI20: 123.21509 | AJ20: 124.31621 | AK20: 125.4141 | AL20: 126.51144 | AM20: 0.01015
B22: Energy Consumption Intensity
B23: (thousand Btu per square foot)
A24: CKI000:ea_DeliveredEner | B24: Delivered Energy Consumption | C24: 97.563316 | D24: 97.668396 | E24: 97.261589 | F24: 96.130386 | G24: 94.564583 | H24: 93.049156 | I24: 91.921562 | J24: 90.789978 | K24: 89.814285 | L24: 89.000862 | M24: 88.169052 | N24: 87.337715 | O24: 86.533424 | P24: 85.845154 | Q24: 85.238655 | R24: 84.562752 | S24: 83.95842 | T24: 83.44989 | U24: 83.066811 | V24: 82.694626 | W24: 82.32798 | X24: 81.971771 | Y24: 81.70665 | Z24: 81.487419 | AA24: 81.290657 | AB24: 81.121017 | AC24: 80.996094 | AD24: 80.906082 | AE24: 80.829742 | AF24: 80.783173 | AG24: 80.748962 | AH24: 80.736008 | AI24: 80.739143 | AJ24: 80.76284 | AK24: 80.817047 | AL24: 80.876205 | AM24: -0.005533
A25: CKI000:ea_ElectricityRe | B25: Electricity Related Losses | C25: 104.5059 | D25: 100.90401 | E25: 99.346626 | F25: 97.71241 | G25: 96.997719 | H25: 96.18927 | I25: 94.948364 | J25: 93.501678 | K25: 92.409111 | L25: 91.170197 | M25: 89.692154 | N25: 87.936859 | O25: 86.59874 | P25: 85.341141 | Q25: 84.346024 | R25: 83.241035 | S25: 82.358757 | T25: 81.451988 | U25: 80.925102 | V25: 80.018387 | W25: 79.049164 | X25: 78.656265 | Y25: 77.88694 | Z25: 77.416069 | AA25: 77.016205 | AB25: 76.765305 | AC25: 76.440575 | AD25: 76.185905 | AE25: 76.056175 | AF25: 75.781189 | AG25: 75.323738 | AH25: 75.058205 | AI25: 74.774857 | AJ25: 74.678268 | AK25: 74.71447 | AL25: 74.367172 | AM25: -0.008935
A26: CKI000:ea_TotalEnergyCo | B26: Total Energy Consumption | C26: 202.06921 | D26: 198.5724 | E26: 196.60822 | F26: 193.8428 | G26: 191.5623 | H26: 189.23843 | I26: 186.86993 | J26: 184.29166 | K26: 182.22339 | L26: 180.17105 | M26: 177.86121 | N26: 175.27457 | O26: 173.13217 | P26: 171.1863 | Q26: 169.58469 | R26: 167.80379 | S26: 166.31717 | T26: 164.90189 | U26: 163.99191 | V26: 162.71301 | W26: 161.37714 | X26: 160.62804 | Y26: 159.5936 | Z26: 158.90349 | AA26: 158.30685 | AB26: 157.88632 | AC26: 157.43668 | AD26: 157.09198 | AE26: 156.88592 | AF26: 156.56436 | AG26: 156.07269 | AH26: 155.79422 | AI26: 155.51401 | AJ26: 155.4411 | AK26: 155.53152 | AL26: 155.24338 | AM26: -0.007214
B28: Delivered Energy Consumption by Fuel
B30: Purchased Electricity
A31: CKI000:ga_SpaceHeating | B31: Space Heating 1/ | C31: 0.117615 | D31: 0.114742 | E31: 0.118186 | F31: 0.118818 | G31: 0.117355 | H31: 0.115732 | I31: 0.114145 | J31: 0.112603 | K31: 0.112238 | L31: 0.112122 | M31: 0.111937 | N31: 0.111655 | O31: 0.111476 | P31: 0.111391 | Q31: 0.111357 | R31: 0.111311 | S31: 0.111322 | T31: 0.111386 | U31: 0.1115 | V31: 0.111669 | W31: 0.111757 | X31: 0.111825 | Y31: 0.111931 | Z31: 0.112083 | AA31: 0.112289 | AB31: 0.112484 | AC31: 0.112711 | AD31: 0.112897 | AE31: 0.11307 | AF31: 0.113239 | AG31: 0.113467 | AH31: 0.11371 | AI31: 0.113946 | AJ31: 0.114183 | AK31: 0.114423 | AL31: 0.114618 | AM31: -3.2e-05
A32: CKI000:ga_SpaceCooling | B32: Space Cooling 1/ | C32: 0.538602 | D32: 0.552436 | E32: 0.496027 | F32: 0.510234 | G32: 0.508443 | H32: 0.505608 | I32: 0.503346 | J32: 0.499632 | K32: 0.497235 | L32: 0.495985 | M32: 0.494195 | N32: 0.492261 | O32: 0.490969 | P32: 0.490298 | Q32: 0.489892 | R32: 0.488986 | S32: 0.48854 | T32: 0.488493 | U32: 0.488845 | V32: 0.489195 | W32: 0.489368 | X32: 0.489373 | Y32: 0.489418 | Z32: 0.489787 | AA32: 0.490245 | AB32: 0.490798 | AC32: 0.49159 | AD32: 0.492416 | AE32: 0.492998 | AF32: 0.493557 | AG32: 0.494229 | AH32: 0.49512 | AI32: 0.496154 | AJ32: 0.497129 | AK32: 0.498335 | AL32: 0.499728 | AM32: -0.002945
A33: CKI000:ga_WaterHeating | B33: Water Heating 1/ | C33: 0.01685 | D33: 0.016803 | E33: 0.016725 | F33: 0.016635 | G33: 0.016513 | H33: 0.01636 | I33: 0.016224 | J33: 0.016052 | K33: 0.015891 | L33: 0.015768 | M33: 0.015635 | N33: 0.015491 | O33: 0.015361 | P33: 0.015246 | Q33: 0.015136 | R33: 0.014981 | S33: 0.014836 | T33: 0.014701 | U33: 0.014576 | V33: 0.014455 | W33: 0.014323 | X33: 0.014191 | Y33: 0.014065 | Z33: 0.013945 | AA33: 0.01383 | AB33: 0.013717 | AC33: 0.01361 | AD33: 0.013503 | AE33: 0.013392 | AF33: 0.01328 | AG33: 0.01317 | AH33: 0.013064 | AI33: 0.012959 | AJ33: 0.012857 | AK33: 0.012759 | AL33: 0.01266 | AM33: -0.008291
A34: CKI000:ga_Ventilation | B34: Ventilation | C34: 0.520373 | D34: 0.519781 | E34: 0.518622 | F34: 0.517425 | G34: 0.51517 | H34: 0.510933 | I34: 0.507199 | J34: 0.500866 | K34: 0.495755 | L34: 0.492381 | M34: 0.488387 | N34: 0.476113 | O34: 0.465019 | P34: 0.455059 | Q34: 0.445953 | R34: 0.436851 | S34: 0.428627 | T34: 0.421193 | U34: 0.414522 | V34: 0.408437 | W34: 0.402566 | X34: 0.397058 | Y34: 0.392136 | Z34: 0.387738 | AA34: 0.383791 | AB34: 0.379404 | AC34: 0.375572 | AD34: 0.372041 | AE34: 0.368746 | AF34: 0.365734 | AG34: 0.363124 | AH34: 0.360929 | AI34: 0.35909 | AJ34: 0.357642 | AK34: 0.356553 | AL34: 0.355715 | AM34: -0.011093
A35: CKI000:ga_Cooking | B35: Cooking | C35: 0.083 | D35: 0.082376 | E35: 0.081706 | F35: 0.081171 | G35: 0.080525 | H35: 0.079819 | I35: 0.079147 | J35: 0.078267 | K35: 0.077474 | L35: 0.076891 | M35: 0.076245 | N35: 0.075566 | O35: 0.07496 | P35: 0.074439 | Q35: 0.073959 | R35: 0.073485 | S35: 0.07305 | T35: 0.072663 | U35: 0.072315 | V35: 0.071981 | W35: 0.071607 | X35: 0.071204 | Y35: 0.070826 | Z35: 0.07046 | AA35: 0.0701 | AB35: 0.069743 | AC35: 0.069403 | AD35: 0.069046 | AE35: 0.068663 | AF35: 0.068265 | AG35: 0.067865 | AH35: 0.067469 | AI35: 0.067069 | AJ35: 0.066664 | AK35: 0.066261 | AL35: 0.065851 | AM35: -0.006564
A36: CKI000:ga_Lighting | B36: Lighting | C36: 0.523999 | D36: 0.510052 | E36: 0.500124 | F36: 0.493548 | G36: 0.488328 | H36: 0.472094 | I36: 0.459182 | J36: 0.441689 | K36: 0.427613 | L36: 0.416762 | M36: 0.407285 | N36: 0.398911 | O36: 0.392037 | P36: 0.386517 | Q36: 0.38195 | R36: 0.3684 | S36: 0.356894 | T36: 0.347163 | U36: 0.338905 | V36: 0.331818 | W36: 0.325463 | X36: 0.319859 | Y36: 0.314587 | Z36: 0.310031 | AA36: 0.306067 | AB36: 0.298299 | AC36: 0.291688 | AD36: 0.285767 | AE36: 0.280359 | AF36: 0.275531 | AG36: 0.271385 | AH36: 0.267902 | AI36: 0.264944 | AJ36: 0.262466 | AK36: 0.260421 | AL36: 0.25866 | AM36: -0.019772
A37: CKI000:ga_Refrigeration | B37: Refrigeration | C37: 0.634089 | D37: 0.639811 | E37: 0.645964 | F37: 0.644753 | G37: 0.643874 | H37: 0.644182 | I37: 0.645211 | J37: 0.640736 | K37: 0.637345 | L37: 0.635446 | M37: 0.629494 | N37: 0.624394 | O37: 0.620554 | P37: 0.617923 | Q37: 0.616277 | R37: 0.610648 | S37: 0.606281 | T37: 0.603043 | U37: 0.600864 | V37: 0.599553 | W37: 0.598758 | X37: 0.598455 | Y37: 0.598734 | Z37: 0.599573 | AA37: 0.600909 | AB37: 0.602353 | AC37: 0.604222 | AD37: 0.606346 | AE37: 0.608658 | AF37: 0.611157 | AG37: 0.613924 | AH37: 0.616966 | AI37: 0.620152 | AJ37: 0.623478 | AK37: 0.626939 | AL37: 0.630416 | AM37: -0.000435
A38: CKI000:ga_OfficeEquipme | B38: Office Equipment (PC) | C38: 0.365338 | D38: 0.354525 | E38: 0.34452 | F38: 0.335385 | G38: 0.327694 | H38: 0.320629 | I38: 0.31426 | J38: 0.308729 | K38: 0.303907 | L38: 0.299945 | M38: 0.296641 | N38: 0.294006 | O38: 0.291796 | P38: 0.290475 | Q38: 0.289575 | R38: 0.289021 | S38: 0.288927 | T38: 0.289278 | U38: 0.289624 | V38: 0.289964 | W38: 0.290707 | X38: 0.291398 | Y38: 0.292078 | Z38: 0.292258 | AA38: 0.292422 | AB38: 0.292036 | AC38: 0.291643 | AD38: 0.290173 | AE38: 0.288631 | AF38: 0.285997 | AG38: 0.282804 | AH38: 0.278518 | AI38: 0.273081 | AJ38: 0.266489 | AK38: 0.258721 | AL38: 0.249728 | AM38: -0.010253
A39: CKI000:ha_OfficeEquipme | B39: Office Equipment (non-PC) | C39: 0.22496 | D39: 0.230237 | E39: 0.234301 | F39: 0.237364 | G39: 0.238984 | H39: 0.240379 | I39: 0.242498 | J39: 0.245123 | K39: 0.24846 | L39: 0.253126 | M39: 0.258468 | N39: 0.264748 | O39: 0.270886 | P39: 0.276642 | Q39: 0.282235 | R39: 0.287573 | S39: 0.292722 | T39: 0.297654 | U39: 0.302654 | V39: 0.307184 | W39: 0.311956 | X39: 0.316713 | Y39: 0.321498 | Z39: 0.326062 | AA39: 0.330953 | AB39: 0.336136 | AC39: 0.341378 | AD39: 0.347213 | AE39: 0.353069 | AF39: 0.359255 | AG39: 0.366109 | AH39: 0.373356 | AI39: 0.380948 | AJ39: 0.389212 | AK39: 0.398468 | AL39: 0.408096 | AM39: 0.016978
A40: CKI000:ha_OtherUses | B40: Other Uses 2/ | C40: 1.610098 | D40: 1.620247 | E40: 1.640949 | F40: 1.662894 | G40: 1.684862 | H40: 1.706584 | I40: 1.729402 | J40: 1.754908 | K40: 1.782634 | L40: 1.812415 | M40: 1.84169 | N40: 1.871535 | O40: 1.902552 | P40: 1.933967 | Q40: 1.966662 | R40: 2.000246 | S40: 2.034371 | T40: 2.070113 | U40: 2.106707 | V40: 2.14528 | W40: 2.18447 | X40: 2.224199 | Y40: 2.265902 | Z40: 2.308626 | AA40: 2.352518 | AB40: 2.398015 | AC40: 2.445001 | AD40: 2.493527 | AE40: 2.543769 | AF40: 2.595689 | AG40: 2.648055 | AH40: 2.703204 | AI40: 2.759075 | AJ40: 2.817255 | AK40: 2.877002 | AL40: 2.939303 | AM40: 0.017672
A41: CKI000:ha_DeliveredEner | B41: Delivered Energy | C41: 4.634924 | D41: 4.641009 | E41: 4.597126 | F41: 4.618227 | G41: 4.621747 | H41: 4.612319 | I41: 4.610613 | J41: 4.598606 | K41: 4.598551 | L41: 4.610838 | M41: 4.619977 | N41: 4.62468 | O41: 4.635611 | P41: 4.651956 | Q41: 4.672997 | R41: 4.681503 | S41: 4.695568 | T41: 4.715687 | U41: 4.740512 | V41: 4.769536 | W41: 4.800977 | X41: 4.834274 | Y41: 4.871173 | Z41: 4.910563 | AA41: 4.953123 | AB41: 4.992985 | AC41: 5.036818 | AD41: 5.082929 | AE41: 5.131355 | AF41: 5.181704 | AG41: 5.234133 | AH41: 5.290237 | AI41: 5.347418 | AJ41: 5.407376 | AK41: 5.469881 | AL41: 5.534775 | AM41: 0.005193
B43: Natural Gas
A44: CKI000:ia_SpaceHeating | B44: Space Heating 1/ | C44: 1.640876 | D44: 1.633144 | E44: 1.709228 | F44: 1.708861 | G44: 1.678487 | H44: 1.649726 | I44: 1.633577 | J44: 1.625024 | K44: 1.613136 | L44: 1.600517 | M44: 1.586807 | N44: 1.572712 | O44: 1.556187 | P44: 1.540368 | Q44: 1.52595 | R44: 1.513718 | S44: 1.502507 | T44: 1.492172 | U44: 1.48294 | V44: 1.473183 | W44: 1.460295 | X44: 1.448135 | Y44: 1.436572 | Z44: 1.42605 | AA44: 1.415474 | AB44: 1.406234 | AC44: 1.396859 | AD44: 1.386221 | AE44: 1.374416 | AF44: 1.362187 | AG44: 1.349652 | AH44: 1.337263 | AI44: 1.325298 | AJ44: 1.31269 | AK44: 1.300846 | AL44: 1.288623 | AM44: -0.006944
A45: CKI000:ia_SpaceCooling | B45: Space Cooling 1/ | C45: 0.026705 | D45: 0.027453 | E45: 0.02239 | F45: 0.022995 | G45: 0.022471 | H45: 0.021918 | I45: 0.021529 | J45: 0.021271 | K45: 0.02107 | L45: 0.020832 | M45: 0.020584 | N45: 0.020346 | O45: 0.020073 | P45: 0.019829 | Q45: 0.019621 | R45: 0.019431 | S45: 0.01926 | T45: 0.019103 | U45: 0.018973 | V45: 0.018834 | W45: 0.018684 | X45: 0.018534 | Y45: 0.01838 | Z45: 0.018254 | AA45: 0.018132 | AB45: 0.01803 | AC45: 0.017928 | AD45: 0.017824 | AE45: 0.017703 | AF45: 0.017588 | AG45: 0.01748 | AH45: 0.017376 | AI45: 0.017285 | AJ45: 0.017185 | AK45: 0.017098 | AL45: 0.017014 | AM45: -0.013974
A46: CKI000:ia_WaterHeating | B46: Water Heating 1/ | C46: 0.300335 | D46: 0.306441 | E46: 0.307774 | F46: 0.305597 | G46: 0.302178 | H46: 0.298868 | I46: 0.297736 | J46: 0.29812 | K46: 0.299124 | L46: 0.299963 | M46: 0.300453 | N46: 0.300883 | O46: 0.300126 | P46: 0.299815 | Q46: 0.300039 | R46: 0.300786 | S46: 0.301665 | T46: 0.302754 | U46: 0.304103 | V46: 0.305401 | W46: 0.306231 | X46: 0.307134 | Y46: 0.308025 | Z46: 0.309162 | AA46: 0.310345 | AB46: 0.311842 | AC46: 0.313343 | AD46: 0.314635 | AE46: 0.315545 | AF46: 0.316368 | AG46: 0.317203 | AH46: 0.318095 | AI46: 0.319061 | AJ46: 0.31993 | AK46: 0.320942 | AL46: 0.321787 | AM46: 0.001438
A47: CKI000:ia_Cooking | B47: Cooking | C47: 0.307005 | D47: 0.316486 | E47: 0.320955 | F47: 0.321977 | G47: 0.321466 | H47: 0.321511 | I47: 0.323673 | J47: 0.327564 | K47: 0.332081 | L47: 0.336254 | M47: 0.339971 | N47: 0.343302 | O47: 0.345247 | P47: 0.347761 | Q47: 0.351061 | R47: 0.355069 | S47: 0.359161 | T47: 0.363513 | U47: 0.368203 | V47: 0.372902 | W47: 0.377104 | X47: 0.381333 | Y47: 0.38553 | Z47: 0.390018 | AA47: 0.394166 | AB47: 0.398652 | AC47: 0.403157 | AD47: 0.407446 | AE47: 0.411506 | AF47: 0.415508 | AG47: 0.419547 | AH47: 0.423678 | AI47: 0.427893 | AJ47: 0.431871 | AK47: 0.435965 | AL47: 0.439897 | AM47: 0.009731
A48: CKI000:ia_OtherUses | B48: Other Uses 3/ | C48: 1.026232 | D48: 0.943227 | E48: 0.965487 | F48: 0.959326 | G48: 0.949134 | H48: 0.940362 | I48: 0.937652 | J48: 0.946761 | K48: 0.959593 | L48: 0.973506 | M48: 0.989226 | N48: 1.007028 | O48: 1.022553 | P48: 1.039655 | Q48: 1.058565 | R48: 1.080129 | S48: 1.102665 | T48: 1.126507 | U48: 1.151706 | V48: 1.177127 | W48: 1.20211 | X48: 1.228212 | Y48: 1.255397 | Z48: 1.284112 | AA48: 1.313926 | AB48: 1.345763 | AC48: 1.37868 | AD48: 1.412835 | AE48: 1.448711 | AF48: 1.487147 | AG48: 1.525362 | AH48: 1.563631 | AI48: 1.602402 | AJ48: 1.640671 | AK48: 1.679127 | AL48: 1.717801 | AM48: 0.017789
A49: CKI000:ia_DeliveredEner | B49: Delivered Energy | C49: 3.301152 | D49: 3.226752 | E49: 3.325834 | F49: 3.318756 | G49: 3.273736 | H49: 3.232385 | I49: 3.214168 | J49: 3.21874 | K49: 3.225004 | L49: 3.231071 | M49: 3.237042 | N49: 3.244271 | O49: 3.244186 | P49: 3.247428 | Q49: 3.255235 | R49: 3.269132 | S49: 3.285259 | T49: 3.304047 | U49: 3.325924 | V49: 3.347447 | W49: 3.364423 | X49: 3.383347 | Y49: 3.403905 | Z49: 3.427597 | AA49: 3.452042 | AB49: 3.480521 | AC49: 3.509968 | AD49: 3.53896 | AE49: 3.567882 | AF49: 3.598798 | AG49: 3.629244 | AH49: 3.660043 | AI49: 3.69194 | AJ49: 3.722347 | AK49: 3.753978 | AL49: 3.785122 | AM49: 0.004705
B51: Distillate Fuel Oil
...

Sheet Calculations
A1: Fraction of Commercial Floorspace that is New
B2: 2015 | C2: 2016 | D2: 2017 | E2: 2018 | F2: 2019 | G2: 2020 | H2: 2021 | I2: 2022 | J2: 2023 | K2: 2024 | L2: 2025 | M2: 2026 | N2: 2027 | O2: 2028 | P2: 2029 | Q2: 2030 | R2: 2031 | S2: 2032 | T2: 2033 | U2: 2034 | V2: 2035 | W2: 2036 | X2: 2037 | Y2: 2038 | Z2: 2039 | AA2: 2040 | AB2: 2041 | AC2: 2042 | AD2: 2043 | AE2: 2044 | AF2: 2045 | AG2: 2046 | AH2: 2047 | AI2: 2048 | AJ2: 2049 | AK2: 2050
A3: Commercial floorspace | B3: ='AEO T5'!C19/'AEO T5'!C20 | C3: ='AEO T5'!D19/'AEO T5'!D20 | D3: ='AEO T5'!E19/'AEO T5'!E20 | E3: ='AEO T5'!F19/'AEO T5'!F20 | F3: ='AEO T5'!G19/'AEO T5'!G20 | G3: ='AEO T5'!H19/'AEO T5'!H20 | H3: ='AEO T5'!I19/'AEO T5'!I20 | I3: ='AEO T5'!J19/'AEO T5'!J20 | ... AK3: ='AEO T5'!AL19/'AEO T5'!AL20
A5: Average | B5: =AVERAGE(B3:AK3)
A8: Fraction of Residential Homes that are New
A10: Housing evolution rates from EIA NEMS documentation:
B12: HDR value | C12: (Fraction of homes that survive each year)
A13: Single-family homes | B13: 0.997
A14: Multifamily homes | B14: 0.995
A15: Mobile homes | B15: 0.966
A17: Surviving homes
B18: 2015 | C18: 2016 | D18: 2017 | E18: 2018 | F18: 2019 | G18: 2020 | H18: 2021 | I18: 2022 | J18: 2023 | K18: 2024 | L18: 2025 | M18: 2026 | N18: 2027 | O18: 2028 | P18: 2029 | Q18: 2030 | R18: 2031 | S18: 2032 | T18: 2033 | U18: 2034 | V18: 2035 | W18: 2036 | X18: 2037 | Y18: 2038 | Z18: 2039 | AA18: 2040 | AB18: 2041 | AC18: 2042 | AD18: 2043 | AE18: 2044 | AF18: 2045 | AG18: 2046 | AH18: 2047 | AI18: 2048 | AJ18: 2049 | AK18: 2050
A19: Single-family homes | C19: ='AEO T4'!C17*$B13 | D19: ='AEO T4'!D17*$B13 | E19: ='AEO T4'!E17*$B13 | F19: ='AEO T4'!F17*$B13 | G19: ='AEO T4'!G17*$B13 | H19: ='AEO T4'!H17*$B13 | I19: ='AEO T4'!I17*$B13 | J19: ='AEO T4'!J17*$B13 | ... AK19: ='AEO T4'!AK17*$B13
A20: Multifamily homes | C20: ='AEO T4'!C18*$B14 | D20: ='AEO T4'!D18*$B14 | E20: ='AEO T4'!E18*$B14 | F20: ='AEO T4'!F18*$B14 | G20: ='AEO T4'!G18*$B14 | H20: ='AEO T4'!H18*$B14 | I20: ='AEO T4'!I18*$B14 | J20: ='AEO T4'!J18*$B14 | ... AK20: ='AEO T4'!AK18*$B14
A21: Mobile homes | C21: ='AEO T4'!C19*$B15 | D21: ='AEO T4'!D19*$B15 | E21: ='AEO T4'!E19*$B15 | F21: ='AEO T4'!F19*$B15 | G21: ='AEO T4'!G19*$B15 | H21: ='AEO T4'!H19*$B15 | I21: ='AEO T4'!I19*$B15 | J21: ='AEO T4'!J19*$B15 | ... AK21: ='AEO T4'!AK19*$B15
A23: Newly built homes
B24: 2015 | C24: 2016 | D24: 2017 | E24: 2018 | F24: 2019 | G24: 2020 | H24: 2021 | I24: 2022 | J24: 2023 | K24: 2024 | L24: 2025 | M24: 2026 | N24: 2027 | O24: 2028 | P24: 2029 | Q24: 2030 | R24: 2031 | S24: 2032 | T24: 2033 | U24: 2034 | V24: 2035 | W24: 2036 | X24: 2037 | Y24: 2038 | Z24: 2039 | AA24: 2040 | AB24: 2041 | AC24: 2042 | AD24: 2043 | AE24: 2044 | AF24: 2045 | AG24: 2046 | AH24: 2047 | AI24: 2048 | AJ24: 2049 | AK24: 2050
A25: Single-family homes | C25: ='AEO T4'!D17-C19 | D25: ='AEO T4'!E17-D19 | E25: ='AEO T4'!F17-E19 | F25: ='AEO T4'!G17-F19 | G25: ='AEO T4'!H17-G19 | H25: ='AEO T4'!I17-H19 | I25: ='AEO T4'!J17-I19 | J25: ='AEO T4'!K17-J19 | ... AK25: ='AEO T4'!AL17-AK19
A26: Multifamily homes | C26: ='AEO T4'!D18-C20 | D26: ='AEO T4'!E18-D20 | E26: ='AEO T4'!F18-E20 | F26: ='AEO T4'!G18-F20 | G26: ='AEO T4'!H18-G20 | H26: ='AEO T4'!I18-H20 | I26: ='AEO T4'!J18-I20 | J26: ='AEO T4'!K18-J20 | ... AK26: ='AEO T4'!AL18-AK20
A27: Mobile homes | C27: ='AEO T4'!D19-C21 | D27: ='AEO T4'!E19-D21 | E27: ='AEO T4'!F19-E21 | F27: ='AEO T4'!G19-F21 | G27: ='AEO T4'!H19-G21 | H27: ='AEO T4'!I19-H21 | I27: ='AEO T4'!J19-I21 | J27: ='AEO T4'!K19-J21 | ... AK27: ='AEO T4'!AL19-AK21
A29: Fraction of homes that are new
B30: 2015 | C30: 2016 | D30: 2017 | E30: 2018 | F30: 2019 | G30: 2020 | H30: 2021 | I30: 2022 | J30: 2023 | K30: 2024 | L30: 2025 | M30: 2026 | N30: 2027 | O30: 2028 | P30: 2029 | Q30: 2030 | R30: 2031 | S30: 2032 | T30: 2033 | U30: 2034 | V30: 2035 | W30: 2036 | X30: 2037 | Y30: 2038 | Z30: 2039 | AA30: 2040 | AB30: 2041 | AC30: 2042 | AD30: 2043 | AE30: 2044 | AF30: 2045 | AG30: 2046 | AH30: 2047 | AI30: 2048 | AJ30: 2049 | AK30: 2050
A31: Single-family homes | C31: =C25/C19 | D31: =D25/D19 | E31: =E25/E19 | F31: =F25/F19 | G31: =G25/G19 | H31: =H25/H19 | I31: =I25/I19 | J31: =J25/J19 | ... AK31: =AK25/AK19
A32: Multifamily homes | C32: =C26/C20 | D32: =D26/D20 | E32: =E26/E20 | F32: =F26/F20 | G32: =G26/G20 | H32: =H26/H20 | I32: =I26/I20 | J32: =J26/J20 | ... AK32: =AK26/AK20
A33: Mobile homes | C33: =C27/C21 | D33: =D27/D21 | E33: =E27/E21 | F33: =F27/F21 | G33: =G27/G21 | H33: =H27/H21 | I33: =I27/I21 | J33: =J27/J21 | ... AK33: =AK27/AK21
A35: Average fraction of homes that are new by home type
A36: Single-family homes | B36: =AVERAGE(C31:AK31)
A37: Multifamily homes | B37: =AVERAGE(C32:AK32)
A38: Mobile homes | B38: =AVERAGE(C33:AK33)
A40: Weighted average fraction of homes that are new
A41: All homes | B41: =SUMPRODUCT(B36:B38,'AEO T4'!D17:D19)/SUM('AEO T4'!D17:D19)
A44: Share of Components That is New This Year
A46: The share of new components is the share of old components that are replaced in surviving
A47: buildings, plus the share of components in new buildings (which equals the share of new
A48: buildings, because all components in new buildings are new components).
A50: Share of Buildings that are Surviving
A51: Commercial | B51: =1-B5
A52: Residential | B52: =1-B41
A54: Replacement rate of components in surviving buildings
A55: heating | B55: =1/'Component Lifetimes'!B2
...

Sheet Pre-Calibration Calculated Vals
B1: urban residential | C1: rural residential | D1: commercial
A2: heating | B2: =Calculations!C63 | C2: =B2 | D2: =Calculations!B63
A3: cooling and ventilation | B3: =Calculations!C64 | C3: =B3 | D3: =Calculations!B64
A4: envelope | B4: 0 | C4: 0 | D4: 0
A5: lighting | B5: =Calculations!C65 | C5: =B5 | D5: =Calculations!B65
A6: appliances | B6: =Calculations!C66 | C6: =B6 | D6: =Calculations!B66
A7: other component | B7: =Calculations!C67 | C7: =B7 | D7: =Calculations!B67
A10: For states
B11: Lifetime (yr) | C11: urban residential | D11: rural residential | E11: commercial
A12: heating | B12: 19 | C12: 0.052631579 | D12: 0.052631579 | E12: 0.052631579
A13: cooling and ventilation | B13: 15.833333 | C13: 0.0625 | D13: 0.0625 | E13: 0.0625
A14: envelope | B14: 51.818182 | C14: 0 | D14: 0 | E14: 0
A15: lighting | B15: 9.1324201 | C15: 0.11111111 | D15: 0.11111111 | E15: 0.11111111
A16: appliances | B16: 13.533333 | C16: 0.071428571 | D16: 0.071428571 | E16: 0.071428571
A17: other component | B17: 15.4 | C17: 0.066666667 | D17: 0.066666667 | E17: 0.066666667

Sheet SoCEUtiNTY
A1: Share of New Components Energy Use (dimensionless) | B1: urban residential | C1: rural residential | D1: commercial
A2: heating | B2: 0.0528909 | C2: 0.0528908 | D2: 0.0524449
A3: cooling and ventilation | B3: 0.0628078 | C3: 0.0628079 | D3: 0.0622779
A4: envelope | B4: 0 | C4: 0 | D4: 0
A5: lighting | B5: 0.111658 | C5: 0.111658 | D5: 0.110716
A6: appliances | B6: 0.0717803 | C6: 0.0717802 | D6: 0.0711749
A7: other component | B7: 0.0669948 | C7: 0.0669949 | D7: 0.0664296
