Workbook

Sheet About
A1: BCTR - BAU Carbon Tax Rate | B1: California | C1: 46267
A2: State abbr (derived): | B2: =IFERROR(INDEX(Keys!$A:$A,MATCH($B$1,Keys!$B:$B,0)),"") -> CA
A3: Program (derived): | B3: =IFERROR(INDEX(Keys!$C:$C,MATCH($B$1,Keys!$B:$B,0)),"none") -> CA
A6: Type any state into B1 (yellow). B2/B3 derive the abbreviation and carbon-pricing program.
A8: Program is derived from the State Policies tab (RGGI BCTR / State specific BCTR flags from policies_to_model.xlsx), not a hardcoded state list -- see Keys!C. Raw data is embedded verbatim with full source columns: RGGI_auctions (price/volume time series),
A9: RGGI_Auction66_states (state-level proceeds/allowances), CA_auctions (CARB joint-auction summary), WA_prices / CO_prices / OR_prices (held-constant or scheduled fact cards). All
A10: downstream values are formulas: Calcs averages the clearing/settlement price column per year, deflates to 2012$, regresses 2018-2025 for RGGI/CA, and forecasts; BCTR picks the
A11: active state program via INDEX/MATCH.
A13: RGGI states -> electricity only; clearing price avg x CPI deflator x 0.90718 (short->metric),
A14: linear regression 2018-2025 -> forecast to 2050.
A15: California -> all sectors; settlement price avg x CPI deflator (2012$), regression 2018-2025,
A16: forecast 2026-2030, flat 2031-2050 (AB 398 extends cap authority to 2030).
A17: Washington -> all sectors except industry & LULUCF; most recent observed auction
A18: settlement price deflated to 2012$ and HELD CONSTANT 2023-2050.
A19: Oregon -> transportation/residential/commercial/industry/district-heat-and-hydrogen;
... A106: Built as a clean, formula-driven rebuild with raw data embedded verbatim. Inputs for staff review.

Sheet BCTR
A1: Unit: $/metric ton CO2e | B1: 2020 | C1: 2021 | D1: 2022 | E1: 2023 | F1: 2024 | G1: 2025 | H1: 2026 | I1: 2027 | J1: 2028 | K1: 2029 | L1: 2030 | M1: 2031 | N1: 2032 | O1: 2033 | P1: 2034 | Q1: 2035 | R1: 2036 | S1: 2037 | T1: 2038 | U1: 2039 | V1: 2040 | W1: 2041 | X1: 2042 | Y1: 2043 | Z1: 2044 | AA1: 2045 | AB1: 2046 | AC1: 2047 | AD1: 2048 | AE1: 2049 | AF1: 2050
A2: transportation sector | B2: =IFERROR(INDEX(Calcs!$B$30:$AF$35,MATCH(About!$B$3,Calcs!$A$30:$A$35,0),MATCH(B$1,Calcs!$B$29:$AF$29,0))*INDEX(Keys!$F$2:$M$7,MATCH(About!$B$3,Keys!$E$2:$E$7,0),MATCH($A2,Keys!$F$1:$M$1,0)),0) -> 15.116366 | C2: =IFERROR(INDEX(Calcs!$B$30:$AF$35,MATCH(About!$B$3,Calcs!$A$30:$A$35,0),MATCH(C$1,Calcs!$B$29:$AF$29,0))*INDEX(Keys!$F$2:$M$7,MATCH(About!$B$3,Keys!$E$2:$E$7,0),MATCH($A2,Keys!$F$1:$M$1,0)),0) -> 18.674583 | D2: =IFERROR(INDEX(Calcs!$B$30:$AF$35,MATCH(About!$B$3,Calcs!$A$30:$A$35,0),MATCH(D$1,Calcs!$B$29:$AF$29,0))*INDEX(Keys!$F$2:$M$7,MATCH(About!$B$3,Keys!$E$2:$E$7,0),MATCH($A2,Keys!$F$1:$M$1,0)),0) -> 22.319623 | E2: =IFERROR(INDEX(Calcs!$B$30:$AF$35,MATCH(About!$B$3,Calcs!$A$30:$A$35,0),MATCH(E$1,Calcs!$B$29:$AF$29,0))*INDEX(Keys!$F$2:$M$7,MATCH(About!$B$3,Keys!$E$2:$E$7,0),MATCH($A2,Keys!$F$1:$M$1,0)),0) -> 24.886334 | F2: =IFERROR(INDEX(Calcs!$B$30:$AF$35,MATCH(About!$B$3,Calcs!$A$30:$A$35,0),MATCH(F$1,Calcs!$B$29:$AF$29,0))*INDEX(Keys!$F$2:$M$7,MATCH(About!$B$3,Keys!$E$2:$E$7,0),MATCH($A2,Keys!$F$1:$M$1,0)),0) -> 25.786326 | G2: =IFERROR(INDEX(Calcs!$B$30:$AF$35,MATCH(About!$B$3,Calcs!$A$30:$A$35,0),MATCH(G$1,Calcs!$B$29:$AF$29,0))*INDEX(Keys!$F$2:$M$7,MATCH(About!$B$3,Keys!$E$2:$E$7,0),MATCH($A2,Keys!$F$1:$M$1,0)),0) -> 20.003912 | H2: =IFERROR(INDEX(Calcs!$B$30:$AF$35,MATCH(About!$B$3,Calcs!$A$30:$A$35,0),MATCH(H$1,Calcs!$B$29:$AF$29,0))*INDEX(Keys!$F$2:$M$7,MATCH(About!$B$3,Keys!$E$2:$E$7,0),MATCH($A2,Keys!$F$1:$M$1,0)),0) -> 26.455521 | I2: =IFERROR(INDEX(Calcs!$B$30:$AF$35,MATCH(About!$B$3,Calcs!$A$30:$A$35,0),MATCH(I$1,Calcs!$B$29:$AF$29,0))*INDEX(Keys!$F$2:$M$7,MATCH(About!$B$3,Keys!$E$2:$E$7,0),MATCH($A2,Keys!$F$1:$M$1,0)),0) -> 28.014138 | ... AF2: =IFERROR(INDEX(Calcs!$B$30:$AF$35,MATCH(About!$B$3,Calcs!$A$30:$A$35,0),MATCH(AF$1,Calcs!$B$29:$AF$29,0))*INDEX(Keys!$F$2:$M$7,MATCH(About!$B$3,Keys!$E$2:$E$7,0),MATCH($A2,Keys!$F$1:$M$1,0)),0) -> 32.68999
A3: electricity sector | B3: =IFERROR(INDEX(Calcs!$B$30:$AF$35,MATCH(About!$B$3,Calcs!$A$30:$A$35,0),MATCH(B$1,Calcs!$B$29:$AF$29,0))*INDEX(Keys!$F$2:$M$7,MATCH(About!$B$3,Keys!$E$2:$E$7,0),MATCH($A3,Keys!$F$1:$M$1,0)),0) -> 15.116366 | C3: =IFERROR(INDEX(Calcs!$B$30:$AF$35,MATCH(About!$B$3,Calcs!$A$30:$A$35,0),MATCH(C$1,Calcs!$B$29:$AF$29,0))*INDEX(Keys!$F$2:$M$7,MATCH(About!$B$3,Keys!$E$2:$E$7,0),MATCH($A3,Keys!$F$1:$M$1,0)),0) -> 18.674583 | D3: =IFERROR(INDEX(Calcs!$B$30:$AF$35,MATCH(About!$B$3,Calcs!$A$30:$A$35,0),MATCH(D$1,Calcs!$B$29:$AF$29,0))*INDEX(Keys!$F$2:$M$7,MATCH(About!$B$3,Keys!$E$2:$E$7,0),MATCH($A3,Keys!$F$1:$M$1,0)),0) -> 22.319623 | E3: =IFERROR(INDEX(Calcs!$B$30:$AF$35,MATCH(About!$B$3,Calcs!$A$30:$A$35,0),MATCH(E$1,Calcs!$B$29:$AF$29,0))*INDEX(Keys!$F$2:$M$7,MATCH(About!$B$3,Keys!$E$2:$E$7,0),MATCH($A3,Keys!$F$1:$M$1,0)),0) -> 24.886334 | F3: =IFERROR(INDEX(Calcs!$B$30:$AF$35,MATCH(About!$B$3,Calcs!$A$30:$A$35,0),MATCH(F$1,Calcs!$B$29:$AF$29,0))*INDEX(Keys!$F$2:$M$7,MATCH(About!$B$3,Keys!$E$2:$E$7,0),MATCH($A3,Keys!$F$1:$M$1,0)),0) -> 25.786326 | G3: =IFERROR(INDEX(Calcs!$B$30:$AF$35,MATCH(About!$B$3,Calcs!$A$30:$A$35,0),MATCH(G$1,Calcs!$B$29:$AF$29,0))*INDEX(Keys!$F$2:$M$7,MATCH(About!$B$3,Keys!$E$2:$E$7,0),MATCH($A3,Keys!$F$1:$M$1,0)),0) -> 20.003912 | H3: =IFERROR(INDEX(Calcs!$B$30:$AF$35,MATCH(About!$B$3,Calcs!$A$30:$A$35,0),MATCH(H$1,Calcs!$B$29:$AF$29,0))*INDEX(Keys!$F$2:$M$7,MATCH(About!$B$3,Keys!$E$2:$E$7,0),MATCH($A3,Keys!$F$1:$M$1,0)),0) -> 26.455521 | I3: =IFERROR(INDEX(Calcs!$B$30:$AF$35,MATCH(About!$B$3,Calcs!$A$30:$A$35,0),MATCH(I$1,Calcs!$B$29:$AF$29,0))*INDEX(Keys!$F$2:$M$7,MATCH(About!$B$3,Keys!$E$2:$E$7,0),MATCH($A3,Keys!$F$1:$M$1,0)),0) -> 28.014138 | ... AF3: =IFERROR(INDEX(Calcs!$B$30:$AF$35,MATCH(About!$B$3,Calcs!$A$30:$A$35,0),MATCH(AF$1,Calcs!$B$29:$AF$29,0))*INDEX(Keys!$F$2:$M$7,MATCH(About!$B$3,Keys!$E$2:$E$7,0),MATCH($A3,Keys!$F$1:$M$1,0)),0) -> 32.68999
A4: residential buildings sector | B4: =IFERROR(INDEX(Calcs!$B$30:$AF$35,MATCH(About!$B$3,Calcs!$A$30:$A$35,0),MATCH(B$1,Calcs!$B$29:$AF$29,0))*INDEX(Keys!$F$2:$M$7,MATCH(About!$B$3,Keys!$E$2:$E$7,0),MATCH($A4,Keys!$F$1:$M$1,0)),0) -> 15.116366 | C4: =IFERROR(INDEX(Calcs!$B$30:$AF$35,MATCH(About!$B$3,Calcs!$A$30:$A$35,0),MATCH(C$1,Calcs!$B$29:$AF$29,0))*INDEX(Keys!$F$2:$M$7,MATCH(About!$B$3,Keys!$E$2:$E$7,0),MATCH($A4,Keys!$F$1:$M$1,0)),0) -> 18.674583 | D4: =IFERROR(INDEX(Calcs!$B$30:$AF$35,MATCH(About!$B$3,Calcs!$A$30:$A$35,0),MATCH(D$1,Calcs!$B$29:$AF$29,0))*INDEX(Keys!$F$2:$M$7,MATCH(About!$B$3,Keys!$E$2:$E$7,0),MATCH($A4,Keys!$F$1:$M$1,0)),0) -> 22.319623 | E4: =IFERROR(INDEX(Calcs!$B$30:$AF$35,MATCH(About!$B$3,Calcs!$A$30:$A$35,0),MATCH(E$1,Calcs!$B$29:$AF$29,0))*INDEX(Keys!$F$2:$M$7,MATCH(About!$B$3,Keys!$E$2:$E$7,0),MATCH($A4,Keys!$F$1:$M$1,0)),0) -> 24.886334 | F4: =IFERROR(INDEX(Calcs!$B$30:$AF$35,MATCH(About!$B$3,Calcs!$A$30:$A$35,0),MATCH(F$1,Calcs!$B$29:$AF$29,0))*INDEX(Keys!$F$2:$M$7,MATCH(About!$B$3,Keys!$E$2:$E$7,0),MATCH($A4,Keys!$F$1:$M$1,0)),0) -> 25.786326 | G4: =IFERROR(INDEX(Calcs!$B$30:$AF$35,MATCH(About!$B$3,Calcs!$A$30:$A$35,0),MATCH(G$1,Calcs!$B$29:$AF$29,0))*INDEX(Keys!$F$2:$M$7,MATCH(About!$B$3,Keys!$E$2:$E$7,0),MATCH($A4,Keys!$F$1:$M$1,0)),0) -> 20.003912 | H4: =IFERROR(INDEX(Calcs!$B$30:$AF$35,MATCH(About!$B$3,Calcs!$A$30:$A$35,0),MATCH(H$1,Calcs!$B$29:$AF$29,0))*INDEX(Keys!$F$2:$M$7,MATCH(About!$B$3,Keys!$E$2:$E$7,0),MATCH($A4,Keys!$F$1:$M$1,0)),0) -> 26.455521 | I4: =IFERROR(INDEX(Calcs!$B$30:$AF$35,MATCH(About!$B$3,Calcs!$A$30:$A$35,0),MATCH(I$1,Calcs!$B$29:$AF$29,0))*INDEX(Keys!$F$2:$M$7,MATCH(About!$B$3,Keys!$E$2:$E$7,0),MATCH($A4,Keys!$F$1:$M$1,0)),0) -> 28.014138 | ... AF4: =IFERROR(INDEX(Calcs!$B$30:$AF$35,MATCH(About!$B$3,Calcs!$A$30:$A$35,0),MATCH(AF$1,Calcs!$B$29:$AF$29,0))*INDEX(Keys!$F$2:$M$7,MATCH(About!$B$3,Keys!$E$2:$E$7,0),MATCH($A4,Keys!$F$1:$M$1,0)),0) -> 32.68999
A5: commercial buildings sector | B5: =IFERROR(INDEX(Calcs!$B$30:$AF$35,MATCH(About!$B$3,Calcs!$A$30:$A$35,0),MATCH(B$1,Calcs!$B$29:$AF$29,0))*INDEX(Keys!$F$2:$M$7,MATCH(About!$B$3,Keys!$E$2:$E$7,0),MATCH($A5,Keys!$F$1:$M$1,0)),0) -> 15.116366 | C5: =IFERROR(INDEX(Calcs!$B$30:$AF$35,MATCH(About!$B$3,Calcs!$A$30:$A$35,0),MATCH(C$1,Calcs!$B$29:$AF$29,0))*INDEX(Keys!$F$2:$M$7,MATCH(About!$B$3,Keys!$E$2:$E$7,0),MATCH($A5,Keys!$F$1:$M$1,0)),0) -> 18.674583 | D5: =IFERROR(INDEX(Calcs!$B$30:$AF$35,MATCH(About!$B$3,Calcs!$A$30:$A$35,0),MATCH(D$1,Calcs!$B$29:$AF$29,0))*INDEX(Keys!$F$2:$M$7,MATCH(About!$B$3,Keys!$E$2:$E$7,0),MATCH($A5,Keys!$F$1:$M$1,0)),0) -> 22.319623 | E5: =IFERROR(INDEX(Calcs!$B$30:$AF$35,MATCH(About!$B$3,Calcs!$A$30:$A$35,0),MATCH(E$1,Calcs!$B$29:$AF$29,0))*INDEX(Keys!$F$2:$M$7,MATCH(About!$B$3,Keys!$E$2:$E$7,0),MATCH($A5,Keys!$F$1:$M$1,0)),0) -> 24.886334 | F5: =IFERROR(INDEX(Calcs!$B$30:$AF$35,MATCH(About!$B$3,Calcs!$A$30:$A$35,0),MATCH(F$1,Calcs!$B$29:$AF$29,0))*INDEX(Keys!$F$2:$M$7,MATCH(About!$B$3,Keys!$E$2:$E$7,0),MATCH($A5,Keys!$F$1:$M$1,0)),0) -> 25.786326 | G5: =IFERROR(INDEX(Calcs!$B$30:$AF$35,MATCH(About!$B$3,Calcs!$A$30:$A$35,0),MATCH(G$1,Calcs!$B$29:$AF$29,0))*INDEX(Keys!$F$2:$M$7,MATCH(About!$B$3,Keys!$E$2:$E$7,0),MATCH($A5,Keys!$F$1:$M$1,0)),0) -> 20.003912 | H5: =IFERROR(INDEX(Calcs!$B$30:$AF$35,MATCH(About!$B$3,Calcs!$A$30:$A$35,0),MATCH(H$1,Calcs!$B$29:$AF$29,0))*INDEX(Keys!$F$2:$M$7,MATCH(About!$B$3,Keys!$E$2:$E$7,0),MATCH($A5,Keys!$F$1:$M$1,0)),0) -> 26.455521 | I5: =IFERROR(INDEX(Calcs!$B$30:$AF$35,MATCH(About!$B$3,Calcs!$A$30:$A$35,0),MATCH(I$1,Calcs!$B$29:$AF$29,0))*INDEX(Keys!$F$2:$M$7,MATCH(About!$B$3,Keys!$E$2:$E$7,0),MATCH($A5,Keys!$F$1:$M$1,0)),0) -> 28.014138 | ... AF5: =IFERROR(INDEX(Calcs!$B$30:$AF$35,MATCH(About!$B$3,Calcs!$A$30:$A$35,0),MATCH(AF$1,Calcs!$B$29:$AF$29,0))*INDEX(Keys!$F$2:$M$7,MATCH(About!$B$3,Keys!$E$2:$E$7,0),MATCH($A5,Keys!$F$1:$M$1,0)),0) -> 32.68999
A6: industry sector | B6: =IFERROR(INDEX(Calcs!$B$30:$AF$35,MATCH(About!$B$3,Calcs!$A$30:$A$35,0),MATCH(B$1,Calcs!$B$29:$AF$29,0))*INDEX(Keys!$F$2:$M$7,MATCH(About!$B$3,Keys!$E$2:$E$7,0),MATCH($A6,Keys!$F$1:$M$1,0)),0) -> 15.116366 | C6: =IFERROR(INDEX(Calcs!$B$30:$AF$35,MATCH(About!$B$3,Calcs!$A$30:$A$35,0),MATCH(C$1,Calcs!$B$29:$AF$29,0))*INDEX(Keys!$F$2:$M$7,MATCH(About!$B$3,Keys!$E$2:$E$7,0),MATCH($A6,Keys!$F$1:$M$1,0)),0) -> 18.674583 | D6: =IFERROR(INDEX(Calcs!$B$30:$AF$35,MATCH(About!$B$3,Calcs!$A$30:$A$35,0),MATCH(D$1,Calcs!$B$29:$AF$29,0))*INDEX(Keys!$F$2:$M$7,MATCH(About!$B$3,Keys!$E$2:$E$7,0),MATCH($A6,Keys!$F$1:$M$1,0)),0) -> 22.319623 | E6: =IFERROR(INDEX(Calcs!$B$30:$AF$35,MATCH(About!$B$3,Calcs!$A$30:$A$35,0),MATCH(E$1,Calcs!$B$29:$AF$29,0))*INDEX(Keys!$F$2:$M$7,MATCH(About!$B$3,Keys!$E$2:$E$7,0),MATCH($A6,Keys!$F$1:$M$1,0)),0) -> 24.886334 | F6: =IFERROR(INDEX(Calcs!$B$30:$AF$35,MATCH(About!$B$3,Calcs!$A$30:$A$35,0),MATCH(F$1,Calcs!$B$29:$AF$29,0))*INDEX(Keys!$F$2:$M$7,MATCH(About!$B$3,Keys!$E$2:$E$7,0),MATCH($A6,Keys!$F$1:$M$1,0)),0) -> 25.786326 | G6: =IFERROR(INDEX(Calcs!$B$30:$AF$35,MATCH(About!$B$3,Calcs!$A$30:$A$35,0),MATCH(G$1,Calcs!$B$29:$AF$29,0))*INDEX(Keys!$F$2:$M$7,MATCH(About!$B$3,Keys!$E$2:$E$7,0),MATCH($A6,Keys!$F$1:$M$1,0)),0) -> 20.003912 | H6: =IFERROR(INDEX(Calcs!$B$30:$AF$35,MATCH(About!$B$3,Calcs!$A$30:$A$35,0),MATCH(H$1,Calcs!$B$29:$AF$29,0))*INDEX(Keys!$F$2:$M$7,MATCH(About!$B$3,Keys!$E$2:$E$7,0),MATCH($A6,Keys!$F$1:$M$1,0)),0) -> 26.455521 | I6: =IFERROR(INDEX(Calcs!$B$30:$AF$35,MATCH(About!$B$3,Calcs!$A$30:$A$35,0),MATCH(I$1,Calcs!$B$29:$AF$29,0))*INDEX(Keys!$F$2:$M$7,MATCH(About!$B$3,Keys!$E$2:$E$7,0),MATCH($A6,Keys!$F$1:$M$1,0)),0) -> 28.014138 | ... AF6: =IFERROR(INDEX(Calcs!$B$30:$AF$35,MATCH(About!$B$3,Calcs!$A$30:$A$35,0),MATCH(AF$1,Calcs!$B$29:$AF$29,0))*INDEX(Keys!$F$2:$M$7,MATCH(About!$B$3,Keys!$E$2:$E$7,0),MATCH($A6,Keys!$F$1:$M$1,0)),0) -> 32.68999
A7: district heat and hydrogen sector | B7: =IFERROR(INDEX(Calcs!$B$30:$AF$35,MATCH(About!$B$3,Calcs!$A$30:$A$35,0),MATCH(B$1,Calcs!$B$29:$AF$29,0))*INDEX(Keys!$F$2:$M$7,MATCH(About!$B$3,Keys!$E$2:$E$7,0),MATCH($A7,Keys!$F$1:$M$1,0)),0) -> 15.116366 | C7: =IFERROR(INDEX(Calcs!$B$30:$AF$35,MATCH(About!$B$3,Calcs!$A$30:$A$35,0),MATCH(C$1,Calcs!$B$29:$AF$29,0))*INDEX(Keys!$F$2:$M$7,MATCH(About!$B$3,Keys!$E$2:$E$7,0),MATCH($A7,Keys!$F$1:$M$1,0)),0) -> 18.674583 | D7: =IFERROR(INDEX(Calcs!$B$30:$AF$35,MATCH(About!$B$3,Calcs!$A$30:$A$35,0),MATCH(D$1,Calcs!$B$29:$AF$29,0))*INDEX(Keys!$F$2:$M$7,MATCH(About!$B$3,Keys!$E$2:$E$7,0),MATCH($A7,Keys!$F$1:$M$1,0)),0) -> 22.319623 | E7: =IFERROR(INDEX(Calcs!$B$30:$AF$35,MATCH(About!$B$3,Calcs!$A$30:$A$35,0),MATCH(E$1,Calcs!$B$29:$AF$29,0))*INDEX(Keys!$F$2:$M$7,MATCH(About!$B$3,Keys!$E$2:$E$7,0),MATCH($A7,Keys!$F$1:$M$1,0)),0) -> 24.886334 | F7: =IFERROR(INDEX(Calcs!$B$30:$AF$35,MATCH(About!$B$3,Calcs!$A$30:$A$35,0),MATCH(F$1,Calcs!$B$29:$AF$29,0))*INDEX(Keys!$F$2:$M$7,MATCH(About!$B$3,Keys!$E$2:$E$7,0),MATCH($A7,Keys!$F$1:$M$1,0)),0) -> 25.786326 | G7: =IFERROR(INDEX(Calcs!$B$30:$AF$35,MATCH(About!$B$3,Calcs!$A$30:$A$35,0),MATCH(G$1,Calcs!$B$29:$AF$29,0))*INDEX(Keys!$F$2:$M$7,MATCH(About!$B$3,Keys!$E$2:$E$7,0),MATCH($A7,Keys!$F$1:$M$1,0)),0) -> 20.003912 | H7: =IFERROR(INDEX(Calcs!$B$30:$AF$35,MATCH(About!$B$3,Calcs!$A$30:$A$35,0),MATCH(H$1,Calcs!$B$29:$AF$29,0))*INDEX(Keys!$F$2:$M$7,MATCH(About!$B$3,Keys!$E$2:$E$7,0),MATCH($A7,Keys!$F$1:$M$1,0)),0) -> 26.455521 | I7: =IFERROR(INDEX(Calcs!$B$30:$AF$35,MATCH(About!$B$3,Calcs!$A$30:$A$35,0),MATCH(I$1,Calcs!$B$29:$AF$29,0))*INDEX(Keys!$F$2:$M$7,MATCH(About!$B$3,Keys!$E$2:$E$7,0),MATCH($A7,Keys!$F$1:$M$1,0)),0) -> 28.014138 | ... AF7: =IFERROR(INDEX(Calcs!$B$30:$AF$35,MATCH(About!$B$3,Calcs!$A$30:$A$35,0),MATCH(AF$1,Calcs!$B$29:$AF$29,0))*INDEX(Keys!$F$2:$M$7,MATCH(About!$B$3,Keys!$E$2:$E$7,0),MATCH($A7,Keys!$F$1:$M$1,0)),0) -> 32.68999
A8: LULUCF sector (does not use fuel) | B8: =IFERROR(INDEX(Calcs!$B$30:$AF$35,MATCH(About!$B$3,Calcs!$A$30:$A$35,0),MATCH(B$1,Calcs!$B$29:$AF$29,0))*INDEX(Keys!$F$2:$M$7,MATCH(About!$B$3,Keys!$E$2:$E$7,0),MATCH($A8,Keys!$F$1:$M$1,0)),0) -> 15.116366 | C8: =IFERROR(INDEX(Calcs!$B$30:$AF$35,MATCH(About!$B$3,Calcs!$A$30:$A$35,0),MATCH(C$1,Calcs!$B$29:$AF$29,0))*INDEX(Keys!$F$2:$M$7,MATCH(About!$B$3,Keys!$E$2:$E$7,0),MATCH($A8,Keys!$F$1:$M$1,0)),0) -> 18.674583 | D8: =IFERROR(INDEX(Calcs!$B$30:$AF$35,MATCH(About!$B$3,Calcs!$A$30:$A$35,0),MATCH(D$1,Calcs!$B$29:$AF$29,0))*INDEX(Keys!$F$2:$M$7,MATCH(About!$B$3,Keys!$E$2:$E$7,0),MATCH($A8,Keys!$F$1:$M$1,0)),0) -> 22.319623 | E8: =IFERROR(INDEX(Calcs!$B$30:$AF$35,MATCH(About!$B$3,Calcs!$A$30:$A$35,0),MATCH(E$1,Calcs!$B$29:$AF$29,0))*INDEX(Keys!$F$2:$M$7,MATCH(About!$B$3,Keys!$E$2:$E$7,0),MATCH($A8,Keys!$F$1:$M$1,0)),0) -> 24.886334 | F8: =IFERROR(INDEX(Calcs!$B$30:$AF$35,MATCH(About!$B$3,Calcs!$A$30:$A$35,0),MATCH(F$1,Calcs!$B$29:$AF$29,0))*INDEX(Keys!$F$2:$M$7,MATCH(About!$B$3,Keys!$E$2:$E$7,0),MATCH($A8,Keys!$F$1:$M$1,0)),0) -> 25.786326 | G8: =IFERROR(INDEX(Calcs!$B$30:$AF$35,MATCH(About!$B$3,Calcs!$A$30:$A$35,0),MATCH(G$1,Calcs!$B$29:$AF$29,0))*INDEX(Keys!$F$2:$M$7,MATCH(About!$B$3,Keys!$E$2:$E$7,0),MATCH($A8,Keys!$F$1:$M$1,0)),0) -> 20.003912 | H8: =IFERROR(INDEX(Calcs!$B$30:$AF$35,MATCH(About!$B$3,Calcs!$A$30:$A$35,0),MATCH(H$1,Calcs!$B$29:$AF$29,0))*INDEX(Keys!$F$2:$M$7,MATCH(About!$B$3,Keys!$E$2:$E$7,0),MATCH($A8,Keys!$F$1:$M$1,0)),0) -> 26.455521 | I8: =IFERROR(INDEX(Calcs!$B$30:$AF$35,MATCH(About!$B$3,Calcs!$A$30:$A$35,0),MATCH(I$1,Calcs!$B$29:$AF$29,0))*INDEX(Keys!$F$2:$M$7,MATCH(About!$B$3,Keys!$E$2:$E$7,0),MATCH($A8,Keys!$F$1:$M$1,0)),0) -> 28.014138 | ... AF8: =IFERROR(INDEX(Calcs!$B$30:$AF$35,MATCH(About!$B$3,Calcs!$A$30:$A$35,0),MATCH(AF$1,Calcs!$B$29:$AF$29,0))*INDEX(Keys!$F$2:$M$7,MATCH(About!$B$3,Keys!$E$2:$E$7,0),MATCH($A8,Keys!$F$1:$M$1,0)),0) -> 32.68999
A9: geoengineering sector (uses industry sector rate) | B9: =IFERROR(INDEX(Calcs!$B$30:$AF$35,MATCH(About!$B$3,Calcs!$A$30:$A$35,0),MATCH(B$1,Calcs!$B$29:$AF$29,0))*INDEX(Keys!$F$2:$M$7,MATCH(About!$B$3,Keys!$E$2:$E$7,0),MATCH($A9,Keys!$F$1:$M$1,0)),0) -> 15.116366 | C9: =IFERROR(INDEX(Calcs!$B$30:$AF$35,MATCH(About!$B$3,Calcs!$A$30:$A$35,0),MATCH(C$1,Calcs!$B$29:$AF$29,0))*INDEX(Keys!$F$2:$M$7,MATCH(About!$B$3,Keys!$E$2:$E$7,0),MATCH($A9,Keys!$F$1:$M$1,0)),0) -> 18.674583 | D9: =IFERROR(INDEX(Calcs!$B$30:$AF$35,MATCH(About!$B$3,Calcs!$A$30:$A$35,0),MATCH(D$1,Calcs!$B$29:$AF$29,0))*INDEX(Keys!$F$2:$M$7,MATCH(About!$B$3,Keys!$E$2:$E$7,0),MATCH($A9,Keys!$F$1:$M$1,0)),0) -> 22.319623 | E9: =IFERROR(INDEX(Calcs!$B$30:$AF$35,MATCH(About!$B$3,Calcs!$A$30:$A$35,0),MATCH(E$1,Calcs!$B$29:$AF$29,0))*INDEX(Keys!$F$2:$M$7,MATCH(About!$B$3,Keys!$E$2:$E$7,0),MATCH($A9,Keys!$F$1:$M$1,0)),0) -> 24.886334 | F9: =IFERROR(INDEX(Calcs!$B$30:$AF$35,MATCH(About!$B$3,Calcs!$A$30:$A$35,0),MATCH(F$1,Calcs!$B$29:$AF$29,0))*INDEX(Keys!$F$2:$M$7,MATCH(About!$B$3,Keys!$E$2:$E$7,0),MATCH($A9,Keys!$F$1:$M$1,0)),0) -> 25.786326 | G9: =IFERROR(INDEX(Calcs!$B$30:$AF$35,MATCH(About!$B$3,Calcs!$A$30:$A$35,0),MATCH(G$1,Calcs!$B$29:$AF$29,0))*INDEX(Keys!$F$2:$M$7,MATCH(About!$B$3,Keys!$E$2:$E$7,0),MATCH($A9,Keys!$F$1:$M$1,0)),0) -> 20.003912 | H9: =IFERROR(INDEX(Calcs!$B$30:$AF$35,MATCH(About!$B$3,Calcs!$A$30:$A$35,0),MATCH(H$1,Calcs!$B$29:$AF$29,0))*INDEX(Keys!$F$2:$M$7,MATCH(About!$B$3,Keys!$E$2:$E$7,0),MATCH($A9,Keys!$F$1:$M$1,0)),0) -> 26.455521 | I9: =IFERROR(INDEX(Calcs!$B$30:$AF$35,MATCH(About!$B$3,Calcs!$A$30:$A$35,0),MATCH(I$1,Calcs!$B$29:$AF$29,0))*INDEX(Keys!$F$2:$M$7,MATCH(About!$B$3,Keys!$E$2:$E$7,0),MATCH($A9,Keys!$F$1:$M$1,0)),0) -> 28.014138 | ... AF9: =IFERROR(INDEX(Calcs!$B$30:$AF$35,MATCH(About!$B$3,Calcs!$A$30:$A$35,0),MATCH(AF$1,Calcs!$B$29:$AF$29,0))*INDEX(Keys!$F$2:$M$7,MATCH(About!$B$3,Keys!$E$2:$E$7,0),MATCH($A9,Keys!$F$1:$M$1,0)),0) -> 32.68999

Sheet State Policies
A1: Policy | B1: State | C1: Year Enacted | D1: old policy notes | E1: old policy quant notes | F1: Updated policy notes | G1: RGGI BCTR | H1: State specific BCTR | I1: Adjustments to BFoICStCT | J1: State Abbreviation | K1: Policy Status | L1: Description | M1: category | N1: latest policy link | O1: latest policy name | P1: latest policy year | Q1: eps file name short | R1: eps file name long | S1: eps file notes | T1: new state policy | U1: policy type previously modeled | V1: new cxc policy type | W1: downscaled policy | X1: update action
A2: Carbon Pollution Pricing | B2: California | C2: 2025 | D2: Already modeled in downscale | E2: CA prices used | F2: Already modeled in downscale | H2: Y | J2: CA | K2: enacted | L2: California's Cap-and-Trade Program covers the electricity, buildings, transportation, and industrial sectors, covering around 80% of state emissions. 2025 law extends the program through 2045. | M2: Cross Sector | N2: https://ww2.arb.ca.gov/our-work/programs/cap-and-trade-program | O2: California's Cap-and-Trade Program | P2: 2025 | Q2: BCTR; BFoICStCT | R2: BAU Carbon Tax Rate; BAU Fraction of Industry Category Subject to Carbon Tax | S2: Cap-and-trade/carbon price maps to BAU Carbon Tax Rate | T2: Y | U2: Y | V2: N | W2: Y | X2: possible action, check that updated policy is modeled in downscaled EPS
A3: Carbon Pollution Pricing | B3: Colorado | C3: 2023 | D3: Already modeled in downscale | E3: Co prices used | F3: Already modeled in downscale | H3: Y | J3: CO | K3: enacted | L3: Colorado's baseline-and-credit trading system allows industrial sources emitting over 25,000 metric tons of CO2e per year to generate and purchase credits generated when these sources reduce their emissions more than required for 2030. The system also allows gas distribution utilities to purchase recovered methane credits from eligible projects for use towards their clean heat targets. The industrial market will also expand to allow for midstream oil and gas operators to participate in 2028. | M3: Cross Sector | N3: https://www.sos.state.co.us/CCR/DisplayRule.do?action=ruleinfo&ruleId=3412&deptID=16&agencyID=7&deptName=Department%20of%20Public%20Health%20and%20Environment&agencyName=Air%20Quality%20Control%20Commission&seriesNum=5%20CCR%201001-31 | O3: Colorado Air Quality Control Commission Regulation Number 27, Part D | P3: 2023 | Q3: BCTR; BFoICStCT | R3: BAU Carbon Tax Rate; BAU Fraction of Industry Category Subject to Carbon Tax | S3: Cap-and-trade/carbon price maps to BAU Carbon Tax Rate | T3: Y | U3: Y | V3: N | W3: Y | X3: possible action, check that updated policy is modeled in downscaled EPS
A4: Carbon Pollution Pricing | B4: Connecticut | C4: 2005 | D4: RGGI, already modeled in downscale | E4: RGGI auction prices used | F4: RGGI, already modeled in downscale | G4: Y | J4: CT | K4: enacted | L4: The Regional Greenhouse Gas Initiative (RGGI) covers the electricity sector. | M4: Cross Sector | N4: https://www.rggi.org/ | O4: The Regional Greenhouse Gas Initiative (RGGI) | P4: 2022 | Q4: BCTR; BFoICStCT | R4: BAU Carbon Tax Rate; BAU Fraction of Industry Category Subject to Carbon Tax | S4: Cap-and-trade/carbon price maps to BAU Carbon Tax Rate | T4: N | U4: Y | V4: N | W4: Y | X4: possible action, check that updated policy is modeled in downscaled EPS
A5: Carbon Pollution Pricing | B5: Delaware | C5: 2005 | D5: RGGI, already modeled in downscale | E5: RGGI auction prices used | F5: RGGI, already modeled in downscale | G5: Y | J5: DE | K5: enacted | L5: The Regional Greenhouse Gas Initiative (RGGI) covers the electricity sector. | M5: Cross Sector | N5: https://www.rggi.org/ | O5: The Regional Greenhouse Gas Initiative (RGGI) | P5: 2018 | Q5: BCTR; BFoICStCT | R5: BAU Carbon Tax Rate; BAU Fraction of Industry Category Subject to Carbon Tax | S5: Cap-and-trade/carbon price maps to BAU Carbon Tax Rate | T5: N | U5: Y | V5: N | W5: Y | X5: possible action, check that updated policy is modeled in downscaled EPS
A6: Carbon Pollution Pricing | B6: Maine | C6: 2005 | D6: RGGI, already modeled in downscale | E6: RGGI auction prices used | F6: RGGI, already modeled in downscale | G6: Y | J6: ME | K6: enacted | L6: The Regional Greenhouse Gas Initiative (RGGI) covers the electricity sector. | M6: Cross Sector | N6: https://www.rggi.org/ | O6: The Regional Greenhouse Gas Initiative (RGGI) | P6: 2020 | Q6: BCTR; BFoICStCT | R6: BAU Carbon Tax Rate; BAU Fraction of Industry Category Subject to Carbon Tax | S6: Cap-and-trade/carbon price maps to BAU Carbon Tax Rate | T6: N | U6: Y | V6: N | W6: Y | X6: possible action, check that updated policy is modeled in downscaled EPS
A7: Carbon Pollution Pricing | B7: Maryland | C7: 2007 | D7: RGGI, already modeled in downscale | E7: RGGI auction prices used | F7: RGGI, already modeled in downscale | G7: Y | J7: MD | K7: enacted | L7: The Regional Greenhouse Gas Initiative (RGGI) covers the electricity sector. | M7: Cross Sector | N7: https://www.rggi.org/ | O7: The Regional Greenhouse Gas Initiative (RGGI) | P7: 2007 | Q7: BCTR; BFoICStCT | R7: BAU Carbon Tax Rate; BAU Fraction of Industry Category Subject to Carbon Tax | S7: Cap-and-trade/carbon price maps to BAU Carbon Tax Rate | T7: N | U7: Y | V7: N | W7: Y | X7: possible action, check that updated policy is modeled in downscaled EPS
A8: Carbon Pollution Pricing | B8: Massachusetts | C8: 2007 | D8: RGGI, already modeled in downscale | E8: RGGI auction prices used | F8: RGGI, already modeled in downscale | G8: Y | J8: MA | K8: enacted | L8: The Regional Greenhouse Gas Initiative (RGGI) covers the electricity sector. | M8: Cross Sector | N8: https://www.rggi.org/ | O8: The Regional Greenhouse Gas Initiative (RGGI) | P8: 2024 | Q8: BCTR; BFoICStCT | R8: BAU Carbon Tax Rate; BAU Fraction of Industry Category Subject to Carbon Tax | S8: Cap-and-trade/carbon price maps to BAU Carbon Tax Rate | T8: N | U8: Y | V8: N | W8: Y | X8: possible action, check that updated policy is modeled in downscaled EPS
A9: Carbon Pollution Pricing | B9: New Hampshire | C9: 2005 | D9: RGGI, already modeled in downscale | E9: RGGI auction prices used | F9: RGGI, already modeled in downscale | G9: Y | J9: NH | K9: enacted | L9: The Regional Greenhouse Gas Initiative (RGGI) covers the electricity sector. | M9: Cross Sector | N9: https://www.rggi.org/ | O9: The Regional Greenhouse Gas Initiative (RGGI) | P9: 2022 | Q9: BCTR; BFoICStCT | R9: BAU Carbon Tax Rate; BAU Fraction of Industry Category Subject to Carbon Tax | S9: Cap-and-trade/carbon price maps to BAU Carbon Tax Rate | T9: N | U9: Y | V9: N | W9: Y | X9: possible action, check that updated policy is modeled in downscaled EPS
A10: Carbon Pollution Pricing | B10: New Jersey | C10: 2020 | D10: RGGI, already modeled in downscale | E10: RGGI auction prices used | F10: RGGI, already modeled in downscale | G10: Y | J10: NJ | K10: enacted | L10: The Regional Greenhouse Gas Initiative (RGGI) covers the electricity sector. | M10: Cross Sector | N10: https://www.rggi.org/ | O10: The Regional Greenhouse Gas Initiative (RGGI) | P10: 2019 | Q10: BCTR; BFoICStCT | R10: BAU Carbon Tax Rate; BAU Fraction of Industry Category Subject to Carbon Tax | S10: Cap-and-trade/carbon price maps to BAU Carbon Tax Rate | T10: N | U10: Y | V10: N | W10: Y | X10: possible action, check that updated policy is modeled in downscaled EPS
A11: Carbon Pollution Pricing | B11: New York | C11: 2005 | D11: RGGI, already modeled in downscale | E11: RGGI auction prices used | F11: RGGI, already modeled in downscale | G11: Y | J11: NY | K11: enacted | L11: The Regional Greenhouse Gas Initiative (RGGI) covers the electricity sector. The state is also developing an economywide cap-and-invest program, with implementation beginning in 2026, per a court ruling. | M11: Cross Sector | N11: https://dec.ny.gov/environmental-protection/air-quality/mandatory-greenhouse-gas-reporting | O11: 6 NYCRR Part 253 - Mandatory Greenhouse Gas Reporting | P11: 2025 | Q11: BCTR; BFoICStCT | R11: BAU Carbon Tax Rate; BAU Fraction of Industry Category Subject to Carbon Tax | S11: Cap-and-trade/carbon price maps to BAU Carbon Tax Rate | T11: Y | U11: Y | V11: N | W11: Y | X11: possible action, check that updated policy is modeled in downscaled EPS
A12: Carbon Pollution Pricing | B12: Oregon | C12: 2024 | D12: Excluded from BCTR due to subsector (fossil)-only policy | F12: Need to model fossil-only in industry sector in BFoICStCT | H12: Y | I12: Y | J12: OR | K12: enacted | L12: The Climate Protection Program sets an enforceable declining cap on greenhouse gas emissions from fossil fuels used throughout Oregon, including diesel, gasoline, and natural gas. The program is designed to reduce these emissions by 50% by 2035 and 90% by 2050. | M12: Cross Sector | N12: https://www.oregon.gov/deq/ghgp/cpp/pages/default.aspx | O12: Oregon's Climate Protection Program | P12: 2024 | Q12: BCTR; BFoICStCT | R12: BAU Carbon Tax Rate; BAU Fraction of Industry Category Subject to Carbon Tax | S12: Cap-and-trade/carbon price maps to BAU Carbon Tax Rate | T12: Y | U12: Y | V12: N | W12: Y | X12: possible action, check that updated policy is modeled in downscaled EPS
A13: Carbon Pollution Pricing | B13: Rhode Island | C13: 2007 | D13: RGGI, already modeled in downscale | E13: RGGI auction prices used | F13: RGGI, already modeled in downscale | G13: Y | J13: RI | K13: enacted | L13: The Regional Greenhouse Gas Initiative (RGGI) covers the electricity sector. | M13: Cross Sector | N13: https://www.rggi.org/ | O13: The Regional Greenhouse Gas Initiative (RGGI) | P13: 2023 | Q13: BCTR; BFoICStCT | R13: BAU Carbon Tax Rate; BAU Fraction of Industry Category Subject to Carbon Tax | S13: Cap-and-trade/carbon price maps to BAU Carbon Tax Rate | T13: N | U13: Y | V13: N | W13: Y | X13: possible action, check that updated policy is modeled in downscaled EPS
A14: Carbon Pollution Pricing | B14: Vermont | C14: 2005 | D14: RGGI, already modeled in downscale | E14: RGGI auction prices used | F14: RGGI, already modeled in downscale | G14: Y | J14: VT | K14: enacted | L14: The Regional Greenhouse Gas Initiative (RGGI) covers the electricity sector. Pursuant to Act 148 (H.868), the state issued a study whether to expand regional cap-and-invest program to other sectors, potentially including transportation and heating. The report notes that benefits of a cap-and-invest program would not be fully realized until the mid-2030s, and could not contribute to the 2030 GWSA target, but would more likely to support the 2050 target. | M14: Cross Sector | N14: https://outside.vermont.gov/agency/anr/climatecouncil/Shared%20Documents/Vermont_Climate_Council/VT%20Cap-and-Invest%20Report_Final.pdf?_gl=1*1qbg1cv*_ga*MTk0ODE1MjkwNS4xNzM3NTcyODcy*_ga_V9WQH77KLW*MTc0MTIyNDU2OC4zLjEuMTc0MTIyNTYxOC4wLjAuMA. | O14: Assessment of a Cap-and-Invest Program for Vermont | P14: 2025 | Q14: BCTR; BFoICStCT | R14: BAU Carbon Tax Rate; BAU Fraction of Industry Category Subject to Carbon Tax | S14: Cap-and-trade/carbon price maps to BAU Carbon Tax Rate | T14: Y | U14: Y | V14: N | W14: Y | X14: possible action, check that updated policy is modeled in downscaled EPS
A15: Carbon Pollution Pricing | B15: Washington | C15: 2023 | D15: Already modeled in downscale | E15: WA prices used | F15: Already modeled in downscale | H15: Y | J15: WA | K15: enacted | L15: Washington's Cap-and-Invest Program covers the electricity, buildings, transportation, and industrial sectors, covering around 75% of state emissions. | M15: Cross Sector | N15: https://app.leg.wa.gov/billsummary?BillNumber=1975&Year=2025 | O15: HB 1975 | P15: 2025 | Q15: BCTR; BFoICStCT | R15: BAU Carbon Tax Rate; BAU Fraction of Industry Category Subject to Carbon Tax | S15: Cap-and-trade/carbon price maps to BAU Carbon Tax Rate | T15: Y | U15: Y | V15: N | W15: Y | X15: possible action, check that updated policy is modeled in downscaled EPS

Sheet Calcs
A1: RGGI derivation (clearing price -> 2012$/metric ton)
A2: year | B2: avg $/short ton | C2: 2012$/short ton | D2: 2012$/metric ton
A3: 2018 | B3: =AVERAGEIFS(RGGI_auctions!$G:$G,RGGI_auctions!$A:$A,A3) -> 4.415 | C3: =B3*Keys!$B$53 -> 4.0367553 | D3: =C3*Keys!$D$53 -> 3.6620637
A4: 2019 | B4: =AVERAGEIFS(RGGI_auctions!$G:$G,RGGI_auctions!$A:$A,A4) -> 5.425 | C4: =B4*Keys!$B$54 -> 4.8719474 | D4: =C4*Keys!$D$53 -> 4.4197332
A5: 2020 | B5: =AVERAGEIFS(RGGI_auctions!$G:$G,RGGI_auctions!$A:$A,A5) -> 6.4075 | C5: =B5*Keys!$B$55 -> 5.6841616 | D5: =C5*Keys!$D$53 -> 5.1565577
A6: 2021 | B6: =AVERAGEIFS(RGGI_auctions!$G:$G,RGGI_auctions!$A:$A,A6) -> 9.4675 | C6: =B6*Keys!$B$56 -> 8.0218518 | D6: =C6*Keys!$D$53 -> 7.2772636
A7: 2022 | B7: =AVERAGEIFS(RGGI_auctions!$G:$G,RGGI_auctions!$A:$A,A7) -> 13.46 | C7: =B7*Keys!$B$57 -> 10.559653 | D7: =C7*Keys!$D$53 -> 9.579506
A8: 2023 | B8: =AVERAGEIFS(RGGI_auctions!$G:$G,RGGI_auctions!$A:$A,A8) -> 13.49 | C8: =B8*Keys!$B$58 -> 10.164761 | D8: =C8*Keys!$D$53 -> 9.221268
A9: 2024 | B9: =AVERAGEIFS(RGGI_auctions!$G:$G,RGGI_auctions!$A:$A,A9) -> 20.7075 | C9: =B9*Keys!$B$59 -> 15.155619 | D9: =C9*Keys!$D$53 -> 13.748875
A10: 2025 | B10: =AVERAGEIFS(RGGI_auctions!$G:$G,RGGI_auctions!$A:$A,A10) -> 22.0925 | C10: =B10*Keys!$B$60 -> 15.752501 | D10: =C10*Keys!$D$53 -> 14.290354
A12: slope | B12: =SLOPE(D3:D10,A3:A10) -> 1.6135728
A13: intercept | B13: =INTERCEPT(D3:D10,A3:A10) -> -3253.4179
A15: CA derivation (settlement price -> 2012$/metric ton)
A16: year | B16: avg $/metric ton | C16: 2012$/metric ton
A17: 2018 | B17: =AVERAGEIFS(CA_auctions!$E:$E,CA_auctions!$A:$A,A17) -> 14.905 | C17: =B17*Keys!$B$53 -> 13.628049
A18: 2019 | B18: =AVERAGEIFS(CA_auctions!$E:$E,CA_auctions!$A:$A,A18) -> 16.835 | C18: =B18*Keys!$B$54 -> 15.118753
A19: 2020 | B19: =AVERAGEIFS(CA_auctions!$E:$E,CA_auctions!$A:$A,A19) -> 17.04 | C19: =B19*Keys!$B$55 -> 15.116366
A20: 2021 | B20: =AVERAGEIFS(CA_auctions!$E:$E,CA_auctions!$A:$A,A20) -> 22.04 | C20: =B20*Keys!$B$56 -> 18.674583
A21: 2022 | B21: =AVERAGEIFS(CA_auctions!$E:$E,CA_auctions!$A:$A,A21) -> 28.45 | C21: =B21*Keys!$B$57 -> 22.319623
A22: 2023 | B22: =AVERAGEIFS(CA_auctions!$E:$E,CA_auctions!$A:$A,A22) -> 33.0275 | C22: =B22*Keys!$B$58 -> 24.886334
A23: 2024 | B23: =AVERAGEIFS(CA_auctions!$E:$E,CA_auctions!$A:$A,A23) -> 35.2325 | C23: =B23*Keys!$B$59 -> 25.786326
A24: 2025 | B24: =AVERAGEIFS(CA_auctions!$E:$E,CA_auctions!$A:$A,A24) -> 28.055 | C24: =B24*Keys!$B$60 -> 20.003912
A25: slope | B25: =SLOPE(C17:C24,A17:A24) -> 1.5586173
A26: intercept | B26: =INTERCEPT(C17:C24,A17:A24) -> -3131.3031
A28: Program price by year (2012$/metric ton; WA/CO/OR nominal held constant)
A29: program | B29: 2020 | C29: 2021 | D29: 2022 | E29: 2023 | F29: 2024 | G29: 2025 | H29: 2026 | I29: 2027 | J29: 2028 | K29: 2029 | L29: 2030 | M29: 2031 | N29: 2032 | O29: 2033 | P29: 2034 | Q29: 2035 | R29: 2036 | S29: 2037 | T29: 2038 | U29: 2039 | V29: 2040 | W29: 2041 | X29: 2042 | Y29: 2043 | Z29: 2044 | AA29: 2045 | AB29: 2046 | AC29: 2047 | AD29: 2048 | AE29: 2049 | AF29: 2050
A30: RGGI | B30: =D5 -> 5.1565577 | C30: =D6 -> 7.2772636 | D30: =D7 -> 9.579506 | E30: =D8 -> 9.221268 | F30: =D9 -> 13.748875 | G30: =D10 -> 14.290354 | H30: =H$29*$B$12+$B$13 -> 15.68053 | I30: =I$29*$B$12+$B$13 -> 17.294103 | J30: =J$29*$B$12+$B$13 -> 18.907676 | K30: =K$29*$B$12+$B$13 -> 20.521249 | L30: =L$29*$B$12+$B$13 -> 22.134821 | M30: =M$29*$B$12+$B$13 -> 23.748394 | N30: =N$29*$B$12+$B$13 -> 25.361967 | O30: =O$29*$B$12+$B$13 -> 26.97554 | ... AF30: =AF$29*$B$12+$B$13 -> 54.406277
A31: CA | B31: =C19 -> 15.116366 | C31: =C20 -> 18.674583 | D31: =C21 -> 22.319623 | E31: =C22 -> 24.886334 | F31: =C23 -> 25.786326 | G31: =C24 -> 20.003912 | H31: =H$29*$B$25+$B$26 -> 26.455521 | I31: =I$29*$B$25+$B$26 -> 28.014138 | J31: =J$29*$B$25+$B$26 -> 29.572756 | K31: =K$29*$B$25+$B$26 -> 31.131373 | L31: =L$29*$B$25+$B$26 -> 32.68999 | M31: =L31 -> 32.68999 | N31: =M31 -> 32.68999 | O31: =N31 -> 32.68999 | P31: =O31 -> 32.68999 | Q31: =P31 -> 32.68999 | R31: =Q31 -> 32.68999 | S31: =R31 -> 32.68999 | T31: =S31 -> 32.68999 | ... AF31: =AE31 -> 32.68999
A32: WA | B32: 0 | C32: 0 | D32: 0 | E32: =E38*(1-E39)+E31*E39 -> 41.335314 | F32: =F38*(1-F39)+F31*F39 -> 23.021611 | G32: =G38*(1-G39)+G31*G39 -> 43.435691 | H32: =H38*(1-H39)+H31*H39 -> 44.47008 | I32: =I38*(1-I39)+I31*I39 -> 38.984771 | J32: =J38*(1-J39)+J31*J39 -> 34.538525 | K32: =K38*(1-K39)+K31*K39 -> 31.131373 | L32: =L38*(1-L39)+L31*L39 -> 32.68999 | ... AF32: =AF38*(1-AF39)+AF31*AF39 -> 32.68999
A33: CO | B33: 0 | C33: 0 | D33: 0 | E33: 0 | F33: 0 | G33: =CO_prices!$B$6 -> 17.059082 | H33: =CO_prices!$B$6 -> 17.059082 | I33: =CO_prices!$B$6 -> 17.059082 | J33: =CO_prices!$B$6 -> 17.059082 | K33: =CO_prices!$B$6 -> 17.059082 | L33: =CO_prices!$B$6 -> 17.059082 | M33: 0 | N33: 0 | O33: 0 | P33: 0 | Q33: 0 | R33: 0 | S33: 0 | T33: 0 | U33: 0 | V33: 0 | W33: 0 | X33: 0 | Y33: 0 | Z33: 0 | AA33: 0 | AB33: 0 | AC33: 0 | AD33: 0 | AE33: 0 | AF33: 0
A34: OR | B34: 0 | C34: 0 | D34: 0 | E34: 0 | F34: 0 | G34: =OR_prices!$C$14 -> 94.413854 | H34: =OR_prices!$C$15 -> 94.413854 | I34: =OR_prices!$C$16 -> 95.145744 | J34: =OR_prices!$C$17 -> 95.877635 | K34: =OR_prices!$C$18 -> 96.609525 | L34: =OR_prices!$C$19 -> 97.341415 | M34: =OR_prices!$C$20 -> 98.073306 | N34: =OR_prices!$C$21 -> 98.805196 | O34: =OR_prices!$C$22 -> 99.537086 | P34: =OR_prices!$C$23 -> 100.26898 | Q34: =OR_prices!$C$24 -> 101.00087 | R34: =OR_prices!$C$25 -> 101.73276 | S34: =OR_prices!$C$26 -> 102.46465 | T34: =OR_prices!$C$27 -> 103.19654 | U34: =OR_prices!$C$28 -> 103.92843 | V34: =OR_prices!$C$29 -> 104.66032 | W34: =OR_prices!$C$30 -> 105.39221 | X34: =OR_prices!$C$31 -> 106.1241 | Y34: =OR_prices!$C$32 -> 106.85599 | Z34: =OR_prices!$C$33 -> 107.58788 | AA34: =OR_prices!$C$34 -> 108.31977 | AB34: =OR_prices!$C$35 -> 109.05166 | AC34: =OR_prices!$C$36 -> 109.78355 | AD34: =OR_prices!$C$37 -> 110.51544 | AE34: =OR_prices!$C$38 -> 111.24733 | AF34: =OR_prices!$C$39 -> 111.97922
A35: none | B35: 0 | C35: 0 | D35: 0 | E35: 0 | F35: 0 | G35: 0 | H35: 0 | I35: 0 | J35: 0 | K35: 0 | L35: 0 | M35: 0 | N35: 0 | O35: 0 | P35: 0 | Q35: 0 | R35: 0 | S35: 0 | T35: 0 | U35: 0 | V35: 0 | W35: 0 | X35: 0 | Y35: 0 | Z35: 0 | AA35: 0 | AB35: 0 | AC35: 0 | AD35: 0 | AE35: 0 | AF35: 0
A37: WA linkage build-up (helper rows for the WA row above; see WA_* constants)
A38: WA standalone price (own auctions; 2026 avg held flat after) | B38: 0 | C38: 0 | D38: 0 | E38: =WA_auctions!$E$33 -> 41.335314 | F38: =WA_auctions!$E$34 -> 23.021611 | G38: =WA_auctions!$E$35 -> 43.435691 | H38: =WA_auctions!$E$36 -> 44.47008 | I38: =WA_auctions!$E$36 -> 44.47008 | J38: =WA_auctions!$E$36 -> 44.47008 | K38: =WA_auctions!$E$36 -> 44.47008 | L38: =WA_auctions!$E$36 -> 44.47008 | M38: =WA_auctions!$E$36 -> 44.47008 | N38: =WA_auctions!$E$36 -> 44.47008 | O38: =WA_auctions!$E$36 -> 44.47008 | ... AF38: =WA_auctions!$E$36 -> 44.47008
A39: linked-market weight (0 = WA alone, 1 = CA price; glide 2027-2029) | B39: 0 | C39: 0 | D39: 0 | E39: 0 | F39: 0 | G39: 0 | H39: 0 | I39: 0.333333 | J39: 0.666667 | K39: 1 | L39: 1 | M39: 1 | N39: 1 | O39: 1 | P39: 1 | Q39: 1 | R39: 1 | S39: 1 | T39: 1 | U39: 1 | V39: 1 | W39: 1 | X39: 1 | Y39: 1 | Z39: 1 | AA39: 1 | AB39: 1 | AC39: 1 | AD39: 1 | AE39: 1 | AF39: 1

Sheet Keys
A1: state_abbr | B1: state_name | C1: program | E1: program | F1: transportation sector | G1: electricity sector | H1: residential buildings sector | I1: commercial buildings sector | J1: industry sector | K1: district heat and hydrogen sector | L1: LULUCF sector (does not use fuel) | M1: geoengineering sector (uses industry sector rate)
A2: AL | B2: Alabama | C2: =IF(COUNTIFS('State Policies'!$J:$J,$A2,'State Policies'!$G:$G,"Y")>0,"RGGI",IF(COUNTIFS('State Policies'!$J:$J,$A2,'State Policies'!$H:$H,"Y")>0,$A2,"none")) -> none | E2: RGGI | F2: 0 | G2: 1 | H2: 0 | I2: 0 | J2: 0 | K2: 0 | L2: 0 | M2: 0
A3: AR | B3: Arkansas | C3: =IF(COUNTIFS('State Policies'!$J:$J,$A3,'State Policies'!$G:$G,"Y")>0,"RGGI",IF(COUNTIFS('State Policies'!$J:$J,$A3,'State Policies'!$H:$H,"Y")>0,$A3,"none")) -> none | E3: CA | F3: 1 | G3: 1 | H3: 1 | I3: 1 | J3: 1 | K3: 1 | L3: 1 | M3: 1
A4: AZ | B4: Arizona | C4: =IF(COUNTIFS('State Policies'!$J:$J,$A4,'State Policies'!$G:$G,"Y")>0,"RGGI",IF(COUNTIFS('State Policies'!$J:$J,$A4,'State Policies'!$H:$H,"Y")>0,$A4,"none")) -> none | E4: WA | F4: 1 | G4: 1 | H4: 1 | I4: 1 | J4: 0 | K4: 1 | L4: 0 | M4: 1
A5: CA | B5: California | C5: =IF(COUNTIFS('State Policies'!$J:$J,$A5,'State Policies'!$G:$G,"Y")>0,"RGGI",IF(COUNTIFS('State Policies'!$J:$J,$A5,'State Policies'!$H:$H,"Y")>0,$A5,"none")) -> CA | E5: CO | F5: 0 | G5: 0 | H5: 0 | I5: 0 | J5: 0 | K5: 0 | L5: 0 | M5: 0
A6: CO | B6: Colorado | C6: =IF(COUNTIFS('State Policies'!$J:$J,$A6,'State Policies'!$G:$G,"Y")>0,"RGGI",IF(COUNTIFS('State Policies'!$J:$J,$A6,'State Policies'!$H:$H,"Y")>0,$A6,"none")) -> CO | E6: OR | F6: 1 | G6: 0 | H6: 1 | I6: 1 | J6: 1 | K6: 1 | L6: 0 | M6: 1
A7: CT | B7: Connecticut | C7: =IF(COUNTIFS('State Policies'!$J:$J,$A7,'State Policies'!$G:$G,"Y")>0,"RGGI",IF(COUNTIFS('State Policies'!$J:$J,$A7,'State Policies'!$H:$H,"Y")>0,$A7,"none")) -> RGGI | E7: none | F7: 0 | G7: 0 | H7: 0 | I7: 0 | J7: 0 | K7: 0 | L7: 0 | M7: 0
A8: DE | B8: Delaware | C8: =IF(COUNTIFS('State Policies'!$J:$J,$A8,'State Policies'!$G:$G,"Y")>0,"RGGI",IF(COUNTIFS('State Policies'!$J:$J,$A8,'State Policies'!$H:$H,"Y")>0,$A8,"none")) -> RGGI
A9: FL | B9: Florida | C9: =IF(COUNTIFS('State Policies'!$J:$J,$A9,'State Policies'!$G:$G,"Y")>0,"RGGI",IF(COUNTIFS('State Policies'!$J:$J,$A9,'State Policies'!$H:$H,"Y")>0,$A9,"none")) -> none | E9: OR sector flags per OR_prices!Note 7 (DEQ CPP rules). Caveat (OR_prices!Note 8): industry=1 overstates 2025-2027 -- EITE / direct-natural-gas sources are exempt from compliance obligations until the 2028-2029 period, not modeled here.
A10: GA | B10: Georgia | C10: =IF(COUNTIFS('State Policies'!$J:$J,$A10,'State Policies'!$G:$G,"Y")>0,"RGGI",IF(COUNTIFS('State Policies'!$J:$J,$A10,'State Policies'!$H:$H,"Y")>0,$A10,"none")) -> none | E10: CO sector flag: CO auction only applicable to GEMM II facilities. Having industry=1 would overstate compliance. Emissions reductions as a result of GEMM instead modeled in BPE
A11: IA | B11: Iowa | C11: =IF(COUNTIFS('State Policies'!$J:$J,$A11,'State Policies'!$G:$G,"Y")>0,"RGGI",IF(COUNTIFS('State Policies'!$J:$J,$A11,'State Policies'!$H:$H,"Y")>0,$A11,"none")) -> none
A12: ID | B12: Idaho | C12: =IF(COUNTIFS('State Policies'!$J:$J,$A12,'State Policies'!$G:$G,"Y")>0,"RGGI",IF(COUNTIFS('State Policies'!$J:$J,$A12,'State Policies'!$H:$H,"Y")>0,$A12,"none")) -> none
A13: IL | B13: Illinois | C13: =IF(COUNTIFS('State Policies'!$J:$J,$A13,'State Policies'!$G:$G,"Y")>0,"RGGI",IF(COUNTIFS('State Policies'!$J:$J,$A13,'State Policies'!$H:$H,"Y")>0,$A13,"none")) -> none
A14: IN | B14: Indiana | C14: =IF(COUNTIFS('State Policies'!$J:$J,$A14,'State Policies'!$G:$G,"Y")>0,"RGGI",IF(COUNTIFS('State Policies'!$J:$J,$A14,'State Policies'!$H:$H,"Y")>0,$A14,"none")) -> none
A15: KS | B15: Kansas | C15: =IF(COUNTIFS('State Policies'!$J:$J,$A15,'State Policies'!$G:$G,"Y")>0,"RGGI",IF(COUNTIFS('State Policies'!$J:$J,$A15,'State Policies'!$H:$H,"Y")>0,$A15,"none")) -> none
A16: KY | B16: Kentucky | C16: =IF(COUNTIFS('State Policies'!$J:$J,$A16,'State Policies'!$G:$G,"Y")>0,"RGGI",IF(COUNTIFS('State Policies'!$J:$J,$A16,'State Policies'!$H:$H,"Y")>0,$A16,"none")) -> none
A17: LA | B17: Louisiana | C17: =IF(COUNTIFS('State Policies'!$J:$J,$A17,'State Policies'!$G:$G,"Y")>0,"RGGI",IF(COUNTIFS('State Policies'!$J:$J,$A17,'State Policies'!$H:$H,"Y")>0,$A17,"none")) -> none
A18: MA | B18: Massachusetts | C18: =IF(COUNTIFS('State Policies'!$J:$J,$A18,'State Policies'!$G:$G,"Y")>0,"RGGI",IF(COUNTIFS('State Policies'!$J:$J,$A18,'State Policies'!$H:$H,"Y")>0,$A18,"none")) -> RGGI
A19: MD | B19: Maryland | C19: =IF(COUNTIFS('State Policies'!$J:$J,$A19,'State Policies'!$G:$G,"Y")>0,"RGGI",IF(COUNTIFS('State Policies'!$J:$J,$A19,'State Policies'!$H:$H,"Y")>0,$A19,"none")) -> RGGI
A20: ME | B20: Maine | C20: =IF(COUNTIFS('State Policies'!$J:$J,$A20,'State Policies'!$G:$G,"Y")>0,"RGGI",IF(COUNTIFS('State Policies'!$J:$J,$A20,'State Policies'!$H:$H,"Y")>0,$A20,"none")) -> RGGI
A21: MI | B21: Michigan | C21: =IF(COUNTIFS('State Policies'!$J:$J,$A21,'State Policies'!$G:$G,"Y")>0,"RGGI",IF(COUNTIFS('State Policies'!$J:$J,$A21,'State Policies'!$H:$H,"Y")>0,$A21,"none")) -> none
A22: MN | B22: Minnesota | C22: =IF(COUNTIFS('State Policies'!$J:$J,$A22,'State Policies'!$G:$G,"Y")>0,"RGGI",IF(COUNTIFS('State Policies'!$J:$J,$A22,'State Policies'!$H:$H,"Y")>0,$A22,"none")) -> none
... A49: WY | B49: Wyoming | C49: =IF(COUNTIFS('State Policies'!$J:$J,$A49,'State Policies'!$G:$G,"Y")>0,"RGGI",IF(COUNTIFS('State Policies'!$J:$J,$A49,'State Policies'!$H:$H,"Y")>0,$A49,"none")) -> none
A51: CPI deflators to 2012$ (CPI_2012/CPI_year)
A52: year | B52: deflator_2012 | D52: short_to_metric | E52: 2025 deflator uses CPI_2025=322.0 (estimate); 2026 uses CPI-U May 2026 monthly NSA=335.123 (verify vs final BLS CPI-U)
A53: 2018 | B53: 0.91432736 | D53: 0.90718
A54: 2019 | B54: 0.89805482
A55: 2020 | B55: 0.88711067
A56: 2021 | B56: 0.84730413
A57: 2022 | B57: 0.78452102
A58: 2023 | B58: 0.75350342
A59: 2024 | B59: 0.73189034
A60: 2025 | B60: 0.71302484
A61: 2026 | B61: 0.68510368

Sheet RGGI_auctions
A1: Year | B1: Auction | C1: Date | D1: Quantity Offered | E1: CCR Sold | F1: Quantity Sold | G1: Clearing Price | H1: Total Proceeds
A2: 2024 | B2: Auction 64 | C2: 45448 | D2: 16053188 | E2: 0 | F2: 16053188 | G2: 21.03 | H2: 3.3759854e+08
A3: 2024 | B3: Auction 63 | C3: 45364 | D3: 15855879 | E3: 8416278 | F3: 24272157 | G3: 16 | H3: 388354512
A4: 2023 | B4: Auction 62 | C4: 45266 | D4: 22090709 | E4: 5565291 | F4: 27656000 | G4: 14.88 | H4: 411521280
A5: 2023 | B5: Auction 61 | C5: 45175 | D5: 21948358 | E5: 0 | F5: 21948358 | G5: 13.85 | H5: 3.0398476e+08
A6: 2023 | B6: Auction 60 | C6: 45084 | D6: 22026639 | E6: 0 | F6: 22026639 | G6: 12.73 | H6: 2.8039911e+08
A7: 2023 | B7: Auction 59 | C7: 44993 | D7: 21522877 | E7: 0 | F7: 21522877 | G7: 12.5 | H7: 2.6903596e+08
A8: 2022 | B8: Auction 58 | C8: 44902 | D8: 22233203 | E8: 0 | F8: 22233203 | G8: 12.99 | H8: 2.8880931e+08
A9: 2022 | B9: Auction 57 | C9: 44811 | D9: 22404023 | E9: 0 | F9: 22404023 | G9: 13.45 | H9: 3.0133411e+08
A10: 2022 | B10: Auction 56 | C10: 44713 | D10: 22280473 | E10: 0 | F10: 22280473 | G10: 13.9 | H10: 3.0969857e+08
A11: 2022 | B11: Auction 55 | C11: 44629 | D11: 21761269 | E11: 0 | F11: 21761269 | G11: 13.5 | H11: 2.9377713e+08
A12: 2021 | B12: Auction 54 | C12: 44531 | D12: 23121518 | E12: 3919482 | F12: 27041000 | G12: 13 | H12: 351533000
A13: 2021 | B13: Auction 53 | C13: 44447 | D13: 22911423 | E13: 0 | F13: 22911423 | G13: 9.3 | H13: 2.1307623e+08
... A27: 2018 | B27: Auction 39 | C27: 43173 | D27: 13553767 | E27: 0 | F27: 13553767 | G27: 3.79 | H27: 51368777
B28: Auction 38 | C28: 43075 | D28: 14687989 | E28: 0 | F28: 14687989 | G28: 3.8 | H28: 55814358
B29: Auction 37 | C29: 42984 | D29: 14371585 | E29: 0 | F29: 14371585 | G29: 4.35 | H29: 62516395
B30: Auction 36 | C30: 42893 | D30: 14597470 | E30: 0 | F30: 14597470 | G30: 2.53 | H30: 36931599
B31: Auction 35 | C31: 42802 | D31: 14371300 | E31: 0 | F31: 14371300 | G31: 3 | H31: 43113900
B32: Auction 34 | C32: 42711 | D32: 14791315 | E32: 0 | F32: 14791315 | G32: 3.55 | H32: 52509168
B33: Auction 33 | C33: 42620 | D33: 14911315 | E33: 0 | F33: 14911315 | G33: 4.54 | H33: 67697370
B34: Auction 32 | C34: 42522 | D34: 15089652 | E34: 0 | F34: 15089652 | G34: 4.53 | H34: 68356124
B35: Auction 31 | C35: 42438 | D35: 14838732 | E35: 0 | F35: 14838732 | G35: 5.25 | H35: 77903343
B36: Auction 30 | C36: 42340 | D36: 15374274 | E36: 0 | F36: 15374274 | G36: 7.5 | H36: 115307055
B37: Auction 29 | C37: 42256 | D37: 15374294 | E37: 10000000 | F37: 25374294 | G37: 6.02 | H37: 1.5275325e+08
B38: Auction 28 | C38: 42158 | D38: 15507571 | E38: 0 | F38: 15507571 | G38: 5.5 | H38: 85291640
B39: Auction 27 | C39: 42074 | D39: 15272670 | E39: 0 | F39: 15272670 | G39: 5.41 | H39: 82625145
... B43: Auction 23 | C43: 41703 | D43: 18491350 | E43: 5000000 | F43: 23491350 | G43: 4 | H43: 93965400
B44: Auction 22 | C44: 41612 | D44: 38329378 | E44: -- | F44: 38329378 | G44: 3 | H44: 114988134
B45: Auction 21 | C45: 41521 | D45: 38409043 | E45: -- | F45: 38409043 | G45: 2.67 | H45: 1.0255214e+08
B46: Auction 20 | C46: 41430 | D46: 38782076 | E46: -- | F46: 38782076 | G46: 3.21 | H46: 1.2449046e+08
B47: Auction 19 | C47: 41346 | D47: 37835405 | E47: -- | F47: 37835405 | G47: 2.8 | H47: 105939134
B48: Auction 18 | C48: 41248 | D48: 37563083 | E48: -- | F48: 19774000 | G48: 1.93 | H48: 38163820
B49: Auction 17 | C49: 41157 | D49: 37949558 | E49: -- | F49: 24589000 | G49: 1.93 | H49: 47456770
B50: Auction 16 | C50: 41066 | D50: 36426008 | E50: -- | F50: 20941000 | G50: 1.93 | H50: 40416130
B51: Auction 15 | C51: 40982 | D51: 34843858 | E51: -- | F51: 21559000 | G51: 1.93 | H51: 41608870
B52: Auction 14 | C52: 40884 | D52: 42983482 | E52: -- | F52: 27293000 | G52: 1.89 | H52: 51583770
B53: Auction 14 (Future) | C53: 40884 | D53: 1864951 | E53: -- | F53: 0 | G53: -- | H53: --
B54: Auction 13 | C54: 40793 | D54: 42189685 | E54: -- | F54: 7487000 | G54: 1.89 | H54: 14150430
B55: Auction 13 (Future) | C55: 40793 | D55: 1864951 | E55: -- | F55: 0 | G55: -- | H55: --
B56: Auction 12 | C56: 40702 | D56: 42034184 | E56: -- | F56: 12537000 | G56: 1.89 | H56: 25477200
...

Sheet RGGI_Auction66_states
A1: RGGI Auction 66 (June 4, 2025) - State Proceeds and Allowances
A2: State | B2: Auction 66 Allowances Sold | C2: Cumulative Allowances Sold (Auctions 1-66) | D2: Auction 66 Proceeds ($) | E2: Cumulative Proceeds (Auctions 1-66) ($)
A3: Connecticut | B3: 870037 | C3: 86481149 | D3: 17444242 | E3: 4.6987367e+08
A4: Delaware | B4: 634114 | C4: 51272316 | D4: 12713986 | E4: 3.1041372e+08
A5: Maine | B5: 502730 | C5: 43590682 | D5: 10079736 | E5: 2.4613619e+08
A6: Maryland | B6: 2782327 | C6: 264974892 | D6: 55785656 | E6: 1.4139133e+09
A7: Massachusetts | B7: 2150772 | C7: 216223402 | D7: 43122979 | E7: 1.162143e+09
A8: New Hampshire | B8: 725342 | C8: 61911412 | D8: 14543107 | E8: 3.6264681e+08
A9: New Jersey | B9: 2984471 | C9: 114644934 | D9: 59838644 | E9: 9.4534043e+08
A10: New York | B10: 4845845 | C10: 494923792 | D10: 97159192 | E10: 2.6506868e+09
A11: Rhode Island | B11: 347656 | C11: 28268588 | D11: 6970502.8 | E11: 1.7389994e+08
A12: Vermont | B12: 100314 | C12: 9952168 | D12: 2011295.7 | E12: 53611149
A13: Sub-Total | B13: 15943608 | C13: 1372243335 | D13: 3.1966934e+08 | E13: 7.788665e+09
A14: Virginia (Total for Auctions 51 to 62) | C14: 68122314 | E14: 8.2772119e+08
A15: Total Cumulative | C15: 1440365649 | E15: 8.6163862e+09

Sheet CA_auctions
A1: Year | B1: Auction Name | C1: Curr Allow Offered | D1: Curr Allow Sold | E1: Current Auction Settlement Price | F1: Adv Offered | G1: Adv Sold | H1: Adv Settlement Price
B2: California-Quebec Joint Auctions (Aug 2018 - present)
A3: 2026 | B3: May 2026 Joint Auction #47 | C3: 49647415 | D3: 49647415 | E3: 28.81 | F3: 6481750 | G3: 6481750 | H3: 28.76
A4: 2026 | B4: February 2026 Joint Auction #46 | C4: 54975757 | D4: 54975757 | E4: 27.94 | F4: 6481750 | G4: 6263000 | H4: 27.94
A5: 2025 | B5: November 2025 Joint Auction #45 | C5: 51253305 | D5: 51253305 | E5: 28.32 | F5: 6847750 | G5: 6847750 | H5: 29.61
A6: 2025 | B6: August 2025 Joint Auction #44 | C6: 51883970 | D6: 51883970 | E6: 28.76 | F6: 6847750 | G6: 6847750 | H6: 28.5
A7: 2025 | B7: May 2025 Joint Auction #43 | C7: 51069285 | D7: 43865000 | E7: 25.87 | F7: 6847750 | G7: 6847750 | H7: 26.15
A8: 2025 | B8: February 2025 Joint Auction #42 | C8: 51466028 | D8: 51466028 | E8: 29.27 | F8: 6847750 | G8: 6847750 | H8: 28
A9: 2024 | B9: November 2024 Joint Auction #41 | C9: 52629612 | D9: 52629612 | E9: 31.91 | F9: 7211000 | G9: 7211000 | H9: 30.16
A10: 2024 | B10: August 2024 Joint Auction #40 | C10: 51179715 | D10: 51179715 | E10: 30.24 | F10: 7211000 | G10: 7211000 | H10: 29.75
A11: 2024 | B11: May 2024 Joint Auction #39 | C11: 51589488 | D11: 51589488 | E11: 37.02 | F11: 7211000 | G11: 7211000 | H11: 38.35
A12: 2024 | B12: February 2024 Joint Auction #38 | C12: 51216056 | D12: 51216056 | E12: 41.76 | F12: 7211000 | G12: 7211000 | H12: 41
A13: 2023 | B13: November 2023 Joint Auction #37 | C13: 57617565 | D13: 57617565 | E13: 38.73 | F13: 7577000 | G13: 7577000 | H13: 37.4
A14: 2023 | B14: August 2023 Joint Auction #36 | C14: 55760384 | D14: 55760384 | E14: 35.2 | F14: 7577000 | G14: 7577000 | H14: 34.16
... A34: 2018 | B34: August 2018 Joint Auction #16 | C34: 79421265 | D34: 79421265 | E34: 15.05 | F34: 9401500 | G34: 9401500 | H34: 14.9
B35: California-Ontario-Quebec Joint Auctions (Feb-May 2018)
A36: 2018 | B36: May 2018 Joint Auction #15 | C36: 90587738 | D36: 90587738 | E36: 14.65 | F36: 12427950 | G36: 6057000 | H36: 14.53
A37: 2018 | B37: February 2018 Joint Auction #14 | C37: 98215920 | D37: 98215920 | E37: 14.61 | F37: 12427950 | G37: 8576000 | H37: 14.53
B38: California-Quebec Joint Auctions (Nov 2014 - Nov 2017)
A39: 2017 | B39: November 2017 Joint Auction #13 | C39: 79548286 | D39: 79548286 | E39: 15.06 | F39: 9723500 | G39: 9723500 | H39: 14.76
A40: 2017 | B40: August 2017 Joint Auction #12 | C40: 63887833 | D40: 63887833 | E40: 14.75 | F40: 9723500 | G40: 9723500 | H40: 14.55
A41: 2017 | B41: May 2017 Joint Auction #11 | C41: 75311960 | D41: 75311960 | E41: 13.8 | F41: 9723500 | G41: 2117000 | H41: 13.57
A42: 2017 | B42: February 2017 Joint Auction #10 | C42: 65104273 | D42: 11673000 | E42: 13.57 | F42: 9723500 | G42: 701000 | H42: 13.57
A43: 2016 | B43: November 2016 Joint Auction #9 | C43: 87069495 | D43: 76960000 | E43: 12.73 | F43: 10078750 | G43: 1020000 | H43: 12.73
A44: 2016 | B44: August 2016 Joint Auction #8 | C44: 86278410 | D44: 30021000 | E44: 12.73 | F44: 10078750 | G44: 769000 | H44: 12.73
A45: 2016 | B45: May 2016 Joint Auction #7 | C45: 67675951 | D45: 7260000 | E45: 12.73 | F45: 10078750 | G45: 914000 | H45: 12.73
A46: 2016 | B46: February 2016 Joint Auction #6 | C46: 71555827 | D46: 68026000 | E46: 12.73 | F46: 10078750 | G46: 9361000 | H46: 12.73
A47: 2015 | B47: November 2015 Joint Auction #5 | C47: 75113008 | D47: 75113008 | E47: 12.73 | F47: 10431500 | G47: 10431500 | H47: 12.65
A48: 2015 | B48: August 2015 Joint Auction #4 | C48: 73429360 | D48: 73429360 | E48: 12.52 | F48: 10431500 | G48: 10431500 | H48: 12.3
A49: 2015 | B49: May 2015 Joint Auction #3 | C49: 76931627 | D49: 76931627 | E49: 12.29 | F49: 10431500 | G49: 9812000 | H49: 12.1
A50: 2015 | B50: February 2015 Joint Auction #2 | C50: 73610528 | D50: 73610528 | E50: 12.21 | F50: 10431500 | G50: 10431500 | H50: 12.1
A51: 2014 | B51: November 2014 Joint Auction #1 | C51: 23070987 | D51: 23070987 | E51: 12.1 | F51: 10787000 | G51: 10787000 | H51: 11.86
B52: California-Only Auctions (Nov 2012 - Aug 2014)
A53: 2014 | B53: August 2014 Auction #8 | C53: 22473043 | D53: 22473043 | E53: 11.5 | F53: 9260000 | G53: 6470000 | H53: 11.34
A54: 2014 | B54: May 2014 Auction #7 | C54: 16947080 | D54: 16947080 | E54: 11.5 | F54: 9260000 | G54: 4036000 | H54: 11.34
A55: 2014 | B55: February 2014 Auction #6 | C55: 19538695 | D55: 19538695 | E55: 11.48 | F55: 9260000 | G55: 9260000 | H55: 11.38
A56: 2013 | B56: November 2013 Auction #5 | C56: 16614526 | D56: 16614526 | E56: 11.48 | F56: 9560000 | G56: 9560000 | H56: 11.1
A57: 2013 | B57: August 2013 Auction #4 | C57: 13865422 | D57: 13865422 | E57: 12.22 | F57: 9560000 | G57: 9560000 | H57: 11.1
A58: 2013 | B58: May 2013 Auction #3 | C58: 14522048 | D58: 14522048 | E58: 14 | F58: 9560000 | G58: 7515000 | H58: 10.71
A59: 2013 | B59: February 2013 Auction #2 | C59: 12924822 | D59: 12924822 | E59: 13.62 | F59: 9560000 | G59: 4440000 | H59: 10.71
...

Sheet WA_prices
A1: Washington Cap-and-Invest - most recent auction settlement price (held constant)
A2: Auction | B2: Auction #14 (June 4, 2026)
A3: Auction date | B3: 46177
A4: Current-vintage settlement price, $/metric ton CO2e (nominal) | B4: 64.56
A5: Deflator to 2012$ (CPI_2012/CPI_2026) | B5: 0.68510368
A6: Settlement price (2012$/metric ton CO2e) - HELD CONSTANT all years | B6: =B4*B5 -> 44.230293
A7: Future-vintage settlement price (nominal $/metric ton, reference only) | B7: 30
A8: WA Cap-and-Invest program start year | B8: 2023
A9: Source | B9: https://ecology.wa.gov/air-climate/climate-commitment-act/cap-and-invest/auctions-and-market

Sheet CO_prices
A1: Colorado GEMM - most recent auction settlement price (held constant)
A2: Auction | B2: Auction #1
A3: Auction date | B3: 45813
A4: Current-vintage settlement price, $/metric ton CO2e (nominal) | B4: 24.9
A5: Deflator to 2012$ (CPI_2012/CPI_2026) | B5: 0.68510368
A6: Settlement price (2012$/metric ton CO2e) - HELD CONSTANT all years | B6: =B4*B5 -> 17.059082
A7: CO GEMM auction start year | B7: 2025
A8: Source | B8: https://icapcarbonaction.com/en/ets/usa-colorado-greenhouse-gas-emissions-and-energy-management-manufacturing-regulation
A10: Note: Auction price not included for now considering only select facilities emitting > 25,000 MT/year are eligible. Emissions reductions associated with this policy (GEMM) are instead reflected in BPE

Sheet OR_prices
A1: Oregon Climate Protection Program - DEQ-set CCI credit contribution amount
A2: Price mechanism | B2: No auction - DEQ sets the price by rule and posts an inflation-adjusted amount annually
A3: Current posted amount effective date | B3: 46082
A4: Current posted amount, $/metric ton CO2e (nominal) | B4: 136
A5: Deflator to 2012$ (CPI_2012/CPI_2026) | B5: 0.68510368
A6: Posted amount in 2012$ (cross-check only - see Note 3) | B6: =B4*B5 -> 93.1741
A7: Deflator to 2012$ (CPI_2012/CPI_2024) - basis for schedule below | B7: 0.73189034
A8: Prior posted amount, eff. Mar 1 2025 - Feb 28 2026 (nominal) | B8: 132
A9: OR CPP first compliance period | B9: 2025-2027
A10: Coverage | B10: Covered fuel suppliers: liquid fuels, propane, natural gas
A12: OAR 340-273-9000 Table 6 - CCI credit contribution amount (verbatim), with 2012$ conversion
A13: year (amount effective Mar 1) | B13: Table 6 amount ($2024) | C13: 2012$/metric ton CO2e
A14: 2025 | B14: 129 | C14: =B14*$B$7 -> 94.413854
A15: 2026 | B15: 129 | C15: =B15*$B$7 -> 94.413854
A16: 2027 | B16: 130 | C16: =B16*$B$7 -> 95.145744
A17: 2028 | B17: 131 | C17: =B17*$B$7 -> 95.877635
A18: 2029 | B18: 132 | C18: =B18*$B$7 -> 96.609525
A19: 2030 | B19: 133 | C19: =B19*$B$7 -> 97.341415
A20: 2031 | B20: 134 | C20: =B20*$B$7 -> 98.073306
A21: 2032 | B21: 135 | C21: =B21*$B$7 -> 98.805196
A22: 2033 | B22: 136 | C22: =B22*$B$7 -> 99.537086
A23: 2034 | B23: 137 | C23: =B23*$B$7 -> 100.26898
A24: 2035 | B24: 138 | C24: =B24*$B$7 -> 101.00087
A25: 2036 | B25: 139 | C25: =B25*$B$7 -> 101.73276
... A39: 2050 | B39: 153 | C39: =B39*$B$7 -> 111.97922
A41: NOTES
A42: Note 1 - value to use in Calcs/BCTR | B42: Use column C by year (2012$/metric ton), i.e. OR_prices!$C$14:$C$39 for 2025-2050. All years 2020-2024 = 0: the 2021 CPP (Div 271) was invalidated by the Oregon Court of Appeals and the readopted program (Div 273) starts with the 2025 compliance period.
A43: Note 2 - escalation is NOT $1/yr from the start | B43: Table 6 holds $129 ($2024) flat for both March 2025 and March 2026, then increases $1 ($2024) per year from March 2027. Formula equivalent: 129 for 2025-2026, then 129 + (year - 2026). This reaches $153 ($2024) in 2050, matching the table.
A44: Note 3 - two deflator bases give different answers | B44: DEQ indexes with CPI-U West for January (OAR 340-273-0820(3)); this workbook's Keys deflators are national CPI-U. Deflating the posted nominal $136 by the 2026 factor gives 93.17, while the Table 6 real schedule gives 94.41 for 2026. Column C uses the Table 6 real basis, which is internally consistent across all years. B6 is retained only as a cross-check.
A45: Note 4 - amounts are Mar 1 to end of Feb, not calendar years | B45: Each Table 6 amount is effective March 1 through the end of the following February. The year labels in column A are the March-effective year; mapping to calendar years is approximate.
A46: Note 5 - this is not a market clearing price | B46: Unlike CA/WA/RGGI, there is no auction. Compliance instruments are distributed free and traded privately, so the instrument price is unobserved. The CCI amount is a rule-set partial safety valve: CCI credits may cover at most 15% of the obligation in compliance period 1 and 20% thereafter (Table 5).
A47: Note 6 - direction of likely bias | B47: Near term this likely OVERSTATES: the 2025 cap was supplemented by a one-time distribution of early-reduction instruments (OAR 340-273-0400(2)) and banking is allowed, so the cap may not bind. Long term it likely UNDERSTATES: the cap falls from 24,157,161 (2025) to 3,181,497 (2050) while the CCI price rises only ~$1/yr real, and CCI use is capped, so the shadow price can exceed it.
A48: Note 7 - recommended Keys sector flags for OR | B48: transportation 1, residential buildings 1, commercial buildings 1, district heat and hydrogen 1, industry 1, electricity 0, LULUCF 0, geoengineering follows industry.
A49: Note 8 - industry flag of 1 overstates 2025-2027 | B49: Covered EITE and direct-natural-gas sources are exempt from compliance obligations and receive no instruments for 2025-2027 (OAR 340-273-0410(3)), and cannot earn CCI credits before Jan 1 2028. From compliance period 2 (2028-2029) they receive output-based allocations and do carry a per-ton obligation, with Table 8 emission reduction targets declining from 1.0 to 0.45 by 2048-2049. Industrial liquid fuels and propane are covered upstream via fuel suppliers from 2025 regardless, as is non-EITE industrial natural gas delivered by an LDC.
A50: Note 9 - electricity is genuinely out of scope | B50: Natural gas delivered to a generating plant with nominal capacity >= 25 MW is excluded from covered emissions for LDCs, EITE sources and DNG sources alike (OAR 340-273-0110(4)(b)(B)(iv), (5)(b)(B)(iv), (6)(b)(B)(iv)). Oregon's power sector is governed by HB 2021 instead.
